Workbook
Name \p: #REF!
Name \s: #REF!
Name AGE: #REF!
Name AREA: #REF!
Name GROSS: #REF!
Name LOOP: #REF!
Name NET: #REF!
Name NUMBER: #REF!
Name RATIO: #REF!
Name STOP: #REF!

Sheet Cover Page
A1: Client's Input:
A2: Yearly Income | B2: 142609
A3: Gender | B3: Male
A4: Residency from age 18 to age 65 | B4: 15
A6: Time Value:
A7: Interest Rate | B7: 0.03
A10: Optimal solution:
A11: Max PV | B11: =Calculations!$B$19 -> 63813.215
A12: Age to receive payment | B12: =Calculations!$C$19 -> 69
A13: Monthly Payment:
A14: Before age 75 | B14: =Calculations!$B$22 -> 351.46461
A15: 75 and above | B15: =Calculations!$C$22 -> 386.61107
A17: ="You should defer your OAS payment to "&ROUND(MOD(B12*12,12),1)&" months after age "&FLOOR(B12,1)&"." -> You should defer your OAS payment to 0 months after age 69.

Sheet Calculations
F1: X | G1: PV(Benefit) | H1: PV | I1: Max PV | J1: PV(Revised) | K1: PV | L1: Max PV
B2: Income | C2: Gender | D2: Residency | F2: =Payments!B8 -> 65 | G2: {=Payments!DT8:DT128} -> 61623.917 | H2: =IF(G2=MAX($G$2:$G$122),"",G2) -> 61623.917 | I2: =IF(G2=MAX($G$2:$G$122),G2,"") | J2: {='Annuity (Revised)'!C8:C128} -> 61623.917 | K2: =IF(J2=MAX(J$2:J$122),"",J2) -> 61623.917 | L2: =IF(J2=MAX(J$2:J$128),J2,"") | Y2: Below age 75 | Z2: 75 and above
B3: ='Cover Page'!B2 -> 142609 | C3: ='Cover Page'!B3 -> Male | D3: ='Cover Page'!B4 -> 15 | E3: years | F3: =Payments!B9 -> 65.083333 | G3: 61719.147 | H3: =IF(G3=MAX($G$2:$G$122),"",G3) -> 61719.147 | I3: =IF(G3=MAX($G$2:$G$122),G3,"") | J3: 61719.147 | K3: =IF(J3=MAX(J$2:J$122),"",J3) -> 61719.147 | L3: =IF(J3=MAX(J$2:J$128),J3,"") | Y3: 142609 | Z3: 148179
F4: =Payments!B10 -> 65.166667 | G4: 61812.043 | H4: =IF(G4=MAX($G$2:$G$122),"",G4) -> 61812.043 | I4: =IF(G4=MAX($G$2:$G$122),G4,"") | J4: 61812.043 | K4: =IF(J4=MAX(J$2:J$122),"",J4) -> 61812.043 | L4: =IF(J4=MAX(J$2:J$128),J4,"")
B5: Interest Rate | F5: =Payments!B11 -> 65.25 | G5: 61902.617 | H5: =IF(G5=MAX($G$2:$G$122),"",G5) -> 61902.617 | I5: =IF(G5=MAX($G$2:$G$122),G5,"") | J5: 61902.617 | K5: =IF(J5=MAX(J$2:J$122),"",J5) -> 61902.617 | L5: =IF(J5=MAX(J$2:J$128),J5,"") | V5: Recovery tax period | W5: Income year | X5: Minimum income recovery threshold | Y5: Maximum income recovery threshold
B6: ='Cover Page'!B7 -> 0.03 | F6: =Payments!B12 -> 65.333333 | G6: 61990.885 | H6: =IF(G6=MAX($G$2:$G$122),"",G6) -> 61990.885 | I6: =IF(G6=MAX($G$2:$G$122),G6,"") | J6: 61990.885 | K6: =IF(J6=MAX(J$2:J$122),"",J6) -> 61990.885 | L6: =IF(J6=MAX(J$2:J$128),J6,"") | Y6: Age 65 to 74 | Z6: Age 75 and over
F7: =Payments!B13 -> 65.416667 | G7: 62076.86 | H7: =IF(G7=MAX($G$2:$G$122),"",G7) -> 62076.86 | I7: =IF(G7=MAX($G$2:$G$122),G7,"") | J7: 62076.86 | K7: =IF(J7=MAX(J$2:J$122),"",J7) -> 62076.86 | L7: =IF(J7=MAX(J$2:J$128),J7,"") | V7: July 2024 to June 2025 | W7: 2023 | X7: 86912 | Y7: 142609 | Z7: 148179 | AA7: =Z7/Y7 -> 1.0390578
A8: Max Income | C8: 75 and above | F8: =Payments!B14 -> 65.5 | G8: 62160.555 | H8: =IF(G8=MAX($G$2:$G$122),"",G8) -> 62160.555 | I8: =IF(G8=MAX($G$2:$G$122),G8,"") | J8: 62160.555 | K8: =IF(J8=MAX(J$2:J$122),"",J8) -> 62160.555 | L8: =IF(J8=MAX(J$2:J$128),J8,"") | V8: July 2025 to June 2026 | W8: 2024 | X8: 90997 | Y8: 148451 | Z8: 154196 | AA8: =Z8/Y8 -> 1.0386996
B9: 142609 | C9: 148179 | F9: =Payments!B15 -> 65.583333 | G9: 62241.984 | H9: =IF(G9=MAX($G$2:$G$122),"",G9) -> 62241.984 | I9: =IF(G9=MAX($G$2:$G$122),G9,"") | J9: 62241.984 | K9: =IF(J9=MAX(J$2:J$122),"",J9) -> 62241.984 | L9: =IF(J9=MAX(J$2:J$128),J9,"") | V9: July 2026 to June 2027 | W9: 2025 | X9: 93454 | Y9: 151668 | Z9: 157490 | AA9: =Z9/Y9 -> 1.0383865
F10: =Payments!B16 -> 65.666667 | G10: 62321.16 | H10: =IF(G10=MAX($G$2:$G$122),"",G10) -> 62321.16 | I10: =IF(G10=MAX($G$2:$G$122),G10,"") | J10: 62321.16 | K10: =IF(J10=MAX(J$2:J$122),"",J10) -> 62321.16 | L10: =IF(J10=MAX(J$2:J$128),J10,"")
B11: Max PV | C11: Age to receive payment | F11: =Payments!B17 -> 65.75 | G11: 62398.096 | H11: =IF(G11=MAX($G$2:$G$122),"",G11) -> 62398.096 | I11: =IF(G11=MAX($G$2:$G$122),G11,"") | J11: 62398.096 | K11: =IF(J11=MAX(J$2:J$122),"",J11) -> 62398.096 | L11: =IF(J11=MAX(J$2:J$128),J11,"") | X11: =X8/X7 -> 1.0470016 | Y11: =Y8/Y7 -> 1.0409652 | Z11: =Z8/Z7 -> 1.0406063
B12: =MAX(G2:G122) -> 63813.215 | C12: =INDEX(F2:F122, MATCH(MAX(G2:G122), G2:G122, 0)) -> 69 | F12: =Payments!B18 -> 65.833333 | G12: 62472.806 | H12: =IF(G12=MAX($G$2:$G$122),"",G12) -> 62472.806 | I12: =IF(G12=MAX($G$2:$G$122),G12,"") | J12: 62472.806 | K12: =IF(J12=MAX(J$2:J$122),"",J12) -> 62472.806 | L12: =IF(J12=MAX(J$2:J$128),J12,"") | X12: =X9/X8 -> 1.0270009 | Y12: =Y9/Y8 -> 1.0216705 | Z12: =Z9/Z8 -> 1.0213624
F13: =Payments!B19 -> 65.916667 | G13: 62545.304 | H13: =IF(G13=MAX($G$2:$G$122),"",G13) -> 62545.304 | I13: =IF(G13=MAX($G$2:$G$122),G13,"") | J13: 62545.304 | K13: =IF(J13=MAX(J$2:J$122),"",J13) -> 62545.304 | L13: =IF(J13=MAX(J$2:J$128),J13,"")
A14: Monthly Payment | C14: 75 and above | F14: =Payments!B20 -> 66 | G14: 62615.602 | H14: =IF(G14=MAX($G$2:$G$122),"",G14) -> 62615.602 | I14: =IF(G14=MAX($G$2:$G$122),G14,"") | J14: 62615.602 | K14: =IF(J14=MAX(J$2:J$122),"",J14) -> 62615.602 | L14: =IF(J14=MAX(J$2:J$128),J14,"")
B15: =INDEX(Payments!DR8:DR128, MATCH(MAX($G$2:$G$122), $G$2:$G$122, 0)) -> 351.46461 | C15: =INDEX(Payments!DS8:DS128, MATCH(MAX($G$2:$G$122), $G$2:$G$122, 0)) -> 386.61107 | F15: =Payments!B21 -> 66.083333 | G15: 62683.713 | H15: =IF(G15=MAX($G$2:$G$122),"",G15) -> 62683.713 | I15: =IF(G15=MAX($G$2:$G$122),G15,"") | J15: 62683.713 | K15: =IF(J15=MAX(J$2:J$122),"",J15) -> 62683.713 | L15: =IF(J15=MAX(J$2:J$128),J15,"")
F16: =Payments!B22 -> 66.166667 | G16: 62749.673 | H16: =IF(G16=MAX($G$2:$G$122),"",G16) -> 62749.673 | I16: =IF(G16=MAX($G$2:$G$122),G16,"") | J16: 62749.673 | K16: =IF(J16=MAX(J$2:J$122),"",J16) -> 62749.673 | L16: =IF(J16=MAX(J$2:J$128),J16,"")
A17: Revised: | B17: Only matters when Residency less than 15 years | F17: =Payments!B23 -> 66.25 | G17: 62813.496 | H17: =IF(G17=MAX($G$2:$G$122),"",G17) -> 62813.496 | I17: =IF(G17=MAX($G$2:$G$122),G17,"") | J17: 62813.496 | K17: =IF(J17=MAX(J$2:J$122),"",J17) -> 62813.496 | L17: =IF(J17=MAX(J$2:J$128),J17,"")
B18: Max PV | C18: Age to receive payment | F18: =Payments!B24 -> 66.333333 | G18: 62875.194 | H18: =IF(G18=MAX($G$2:$G$122),"",G18) -> 62875.194 | I18: =IF(G18=MAX($G$2:$G$122),G18,"") | J18: 62875.194 | K18: =IF(J18=MAX(J$2:J$122),"",J18) -> 62875.194 | L18: =IF(J18=MAX(J$2:J$128),J18,"")
B19: =MAX(J2:J128) -> 63813.215 | C19: =INDEX(F2:F122, MATCH(MAX(J2:J122), J2:J122, 0)) -> 69 | F19: =Payments!B25 -> 66.416667 | G19: 62934.781 | H19: =IF(G19=MAX($G$2:$G$122),"",G19) -> 62934.781 | I19: =IF(G19=MAX($G$2:$G$122),G19,"") | J19: 62934.781 | K19: =IF(J19=MAX(J$2:J$122),"",J19) -> 62934.781 | L19: =IF(J19=MAX(J$2:J$128),J19,"")
F20: =Payments!B26 -> 66.5 | G20: 62992.27 | H20: =IF(G20=MAX($G$2:$G$122),"",G20) -> 62992.27 | I20: =IF(G20=MAX($G$2:$G$122),G20,"") | J20: 62992.27 | K20: =IF(J20=MAX(J$2:J$122),"",J20) -> 62992.27 | L20: =IF(J20=MAX(J$2:J$128),J20,"")
A21: Monthly Payment | C21: 75 and above | F21: =Payments!B27 -> 66.583333 | G21: 63047.673 | H21: =IF(G21=MAX($G$2:$G$122),"",G21) -> 63047.673 | I21: =IF(G21=MAX($G$2:$G$122),G21,"") | J21: 63047.673 | K21: =IF(J21=MAX(J$2:J$122),"",J21) -> 63047.673 | L21: =IF(J21=MAX(J$2:J$128),J21,"")
B22: =INDEX('Annuity (Revised)'!DS8:DS128, MATCH(MAX($J$2:$J$122), $J$2:$J$122, 0)) -> 351.46461 | C22: =INDEX('Annuity (Revised)'!DT8:DT128, MATCH(MAX($J$2:$J$122), $J$2:$J$122, 0)) -> 386.61107 | F22: =Payments!B28 -> 66.666667 | G22: 63101.005 | H22: =IF(G22=MAX($G$2:$G$122),"",G22) -> 63101.005 | I22: =IF(G22=MAX($G$2:$G$122),G22,"") | J22: 63101.005 | K22: =IF(J22=MAX(J$2:J$122),"",J22) -> 63101.005 | L22: =IF(J22=MAX(J$2:J$128),J22,"")
F23: =Payments!B29 -> 66.75 | G23: 63152.277 | H23: =IF(G23=MAX($G$2:$G$122),"",G23) -> 63152.277 | I23: =IF(G23=MAX($G$2:$G$122),G23,"") | J23: 63152.277 | K23: =IF(J23=MAX(J$2:J$122),"",J23) -> 63152.277 | L23: =IF(J23=MAX(J$2:J$128),J23,"")
F24: =Payments!B30 -> 66.833333 | G24: 63201.502 | H24: =IF(G24=MAX($G$2:$G$122),"",G24) -> 63201.502 | I24: =IF(G24=MAX($G$2:$G$122),G24,"") | J24: 63201.502 | K24: =IF(J24=MAX(J$2:J$122),"",J24) -> 63201.502 | L24: =IF(J24=MAX(J$2:J$128),J24,"")
F25: =Payments!B31 -> 66.916667 | G25: 63248.695 | H25: =IF(G25=MAX($G$2:$G$122),"",G25) -> 63248.695 | I25: =IF(G25=MAX($G$2:$G$122),G25,"") | J25: 63248.695 | K25: =IF(J25=MAX(J$2:J$122),"",J25) -> 63248.695 | L25: =IF(J25=MAX(J$2:J$128),J25,"")
F26: =Payments!B32 -> 67 | G26: 63293.866 | H26: =IF(G26=MAX($G$2:$G$122),"",G26) -> 63293.866 | I26: =IF(G26=MAX($G$2:$G$122),G26,"") | J26: 63293.866 | K26: =IF(J26=MAX(J$2:J$122),"",J26) -> 63293.866 | L26: =IF(J26=MAX(J$2:J$128),J26,"")
F27: =Payments!B33 -> 67.083333 | G27: 63337.029 | H27: =IF(G27=MAX($G$2:$G$122),"",G27) -> 63337.029 | I27: =IF(G27=MAX($G$2:$G$122),G27,"") | J27: 63337.029 | K27: =IF(J27=MAX(J$2:J$122),"",J27) -> 63337.029 | L27: =IF(J27=MAX(J$2:J$128),J27,"")
F28: =Payments!B34 -> 67.166667 | G28: 63378.222 | H28: =IF(G28=MAX($G$2:$G$122),"",G28) -> 63378.222 | I28: =IF(G28=MAX($G$2:$G$122),G28,"") | J28: 63378.222 | K28: =IF(J28=MAX(J$2:J$122),"",J28) -> 63378.222 | L28: =IF(J28=MAX(J$2:J$128),J28,"")
F29: =Payments!B35 -> 67.25 | G29: 63417.458 | H29: =IF(G29=MAX($G$2:$G$122),"",G29) -> 63417.458 | I29: =IF(G29=MAX($G$2:$G$122),G29,"") | J29: 63417.458 | K29: =IF(J29=MAX(J$2:J$122),"",J29) -> 63417.458 | L29: =IF(J29=MAX(J$2:J$128),J29,"")
F30: =Payments!B36 -> 67.333333 | G30: 63454.748 | H30: =IF(G30=MAX($G$2:$G$122),"",G30) -> 63454.748 | I30: =IF(G30=MAX($G$2:$G$122),G30,"") | J30: 63454.748 | K30: =IF(J30=MAX(J$2:J$122),"",J30) -> 63454.748 | L30: =IF(J30=MAX(J$2:J$128),J30,"")
F31: =Payments!B37 -> 67.416667 | G31: 63490.106 | H31: =IF(G31=MAX($G$2:$G$122),"",G31) -> 63490.106 | I31: =IF(G31=MAX($G$2:$G$122),G31,"") | J31: 63490.106 | K31: =IF(J31=MAX(J$2:J$122),"",J31) -> 63490.106 | L31: =IF(J31=MAX(J$2:J$128),J31,"")
F32: =Payments!B38 -> 67.5 | G32: 63523.545 | H32: =IF(G32=MAX($G$2:$G$122),"",G32) -> 63523.545 | I32: =IF(G32=MAX($G$2:$G$122),G32,"") | J32: 63523.545 | K32: =IF(J32=MAX(J$2:J$122),"",J32) -> 63523.545 | L32: =IF(J32=MAX(J$2:J$128),J32,"")
F33: =Payments!B39 -> 67.583333 | G33: 63555.077 | H33: =IF(G33=MAX($G$2:$G$122),"",G33) -> 63555.077 | I33: =IF(G33=MAX($G$2:$G$122),G33,"") | J33: 63555.077 | K33: =IF(J33=MAX(J$2:J$122),"",J33) -> 63555.077 | L33: =IF(J33=MAX(J$2:J$128),J33,"")
F34: =Payments!B40 -> 67.666667 | G34: 63584.715 | H34: =IF(G34=MAX($G$2:$G$122),"",G34) -> 63584.715 | I34: =IF(G34=MAX($G$2:$G$122),G34,"") | J34: 63584.715 | K34: =IF(J34=MAX(J$2:J$122),"",J34) -> 63584.715 | L34: =IF(J34=MAX(J$2:J$128),J34,"")
... F122: =Payments!B128 -> 75 | G122: 47815.985 | H122: =IF(G122=MAX($G$2:$G$122),"",G122) -> 47815.985 | I122: =IF(G122=MAX($G$2:$G$122),G122,"") | J122: 47815.985 | K122: =IF(J122=MAX(J$2:J$122),"",J122) -> 47815.985 | L122: =IF(J122=MAX(J$2:J$128),J122,"")

Sheet StatCan
A1: https://www.soa.org/resources/experience-studies/2015/2017-cso-tables/ | C1: x | D1: q_x | E1: mu_x | F1: A_x | G1: a_x | H1: a(12)_x (UDD) | I1: a(12)_x (WH3) | J1: npx | K1: 0 | L1: 1 | M1: 2 | N1: 3 | O1: 4 | P1: 5 | Q1: 6 | R1: 7 | S1: 8 | T1: 9 | U1: 10 | V1: 11 | W1: 12 | X1: 13 | Y1: 14 | Z1: 15 | AA1: 16 | AB1: 17 | AC1: 18 | AD1: 19 | AE1: 20 | AF1: 21 | AG1: 22 | AH1: 23 | AI1: 24 | AJ1: 25 | AK1: 26 | AL1: 27 | AM1: 28 | AN1: 29 | AO1: 30 | AP1: 31 | AQ1: 32 | AR1: 33 | AS1: 34 | AT1: 35 | AU1: 36 | AV1: 37 | AW1: 38 | AX1: 39 | AY1: 40 | AZ1: 41 | BA1: 42 | BB1: 43 | BC1: 44 | BD1: 45 | BE1: 46 | BF1: 47 | BG1: 48 | BH1: 49 | BI1: 50 | BJ1: 51 | BK1: 52 | BL1: 53 | BM1: 54 | BN1: 55 | BO1: 56 | BP1: 57 | BQ1: 58 | BR1: 59 | BS1: 60 | BT1: 61 | BU1: 62 | BV1: 63 | BW1: 64 | BX1: 65 | BY1: 66 | BZ1: 67 | CA1: 68 | CB1: 69 | CC1: 70 | CD1: 71 | CE1: 72 | CF1: 73 | CG1: 74 | CH1: 75 | CI1: 76 | CJ1: 77 | CK1: 78 | CL1: 79 | CM1: 80 | CN1: 81 | CO1: 82 | CP1: 83 | CQ1: 84 | CR1: 85 | CS1: 86 | CT1: 87 | CU1: 88 | CV1: 89 | CW1: 90 | CX1: 91 | CY1: 92 | CZ1: 93 | DA1: 94 | DB1: 95 | DC1: 96 | DD1: 97 | DE1: 98 | DF1: 99 | DG1: 100 | DH1: 101 | DI1: 102 | DJ1: 103 | DK1: 104 | DL1: 105 | DM1: 106 | DN1: 107 | DO1: 108 | DP1: 109 | DQ1: 110 | DR1: 111 | DS1: 112 | DT1: 113 | DU1: 114 | DV1: 115 | DW1: 116 | DX1: 117 | DZ1: Age group | EA1: 2019 | EB1: 2020 | EC1: 2021 | ED1: 2022 | EE1: 2023 | EF1: Average
C2: 64 | D2: =EF2 -> 0.008422 | K2: 1 | L2: {=IFERROR(K2*(1-INDEX($D2:$D$71,L$1)),0)} -> 0.991578 | M2: {=IFERROR(L2*(1-INDEX($D2:$D$71,M$1)),0)} -> 0.98231005 | N2: {=IFERROR(M2*(1-INDEX($D2:$D$71,N$1)),0)} -> 0.9722512 | O2: {=IFERROR(N2*(1-INDEX($D2:$D$71,O$1)),0)} -> 0.96132957 | P2: {=IFERROR(O2*(1-INDEX($D2:$D$71,P$1)),0)} -> 0.94947638 | Q2: {=IFERROR(P2*(1-INDEX($D2:$D$71,Q$1)),0)} -> 0.93661414 | R2: {=IFERROR(Q2*(1-INDEX($D2:$D$71,R$1)),0)} -> 0.92265235 | S2: {=IFERROR(R2*(1-INDEX($D2:$D$71,S$1)),0)} -> 0.90751162 | ... DX2: {=IFERROR(DW2*(1-INDEX($D2:$D$71,DX$1)),0)} -> 0 | DZ2: 64 years | EA2: 0.00805 | EB2: 0.00843 | EC2: 0.00861 | ED2: 0.00868 | EE2: 0.00834 | EF2: =AVERAGE(EA2:EE2) -> 0.008422 | EG2: =ED2/EC2-1 -> 0.0081300813 | EH2: =EE2/ED2-1 -> -0.039170507
A3: i | C3: 65 | D3: =EF3 -> 0.0093466667 | E3: =-1/2*(LN(1-D2)+LN(1-D3)) -> 0.0089241431 | F3: {=SUMPRODUCT($A$6^($K$1:$DT$1+1),K3:DT3,TRANSPOSE(D3:D116))} -> 0.55223883 | G3: {=SUMPRODUCT($A$6^($K$1:$DT$1),K3:DT3)} -> 15.373134 | H3: =(1-$A$4/$A$9*F3)/$A$15 -> 14.910983 | I3: =G3-(12-1)/2/12-(12^2-1)/12/12^2*(E3+LN(1+$A$4)) -> 14.911616 | K3: 1 | L3: {=IFERROR(K3*(1-INDEX($D3:$D$71,L$1)),0)} -> 0.99065333 | M3: {=IFERROR(L3*(1-INDEX($D3:$D$71,M$1)),0)} -> 0.98050904 | N3: {=IFERROR(M3*(1-INDEX($D3:$D$71,N$1)),0)} -> 0.96949466 | O3: {=IFERROR(N3*(1-INDEX($D3:$D$71,O$1)),0)} -> 0.95754079 | P3: {=IFERROR(O3*(1-INDEX($D3:$D$71,P$1)),0)} -> 0.9445693 | Q3: {=IFERROR(P3*(1-INDEX($D3:$D$71,Q$1)),0)} -> 0.93048892 | R3: {=IFERROR(Q3*(1-INDEX($D3:$D$71,R$1)),0)} -> 0.9152196 | S3: {=IFERROR(R3*(1-INDEX($D3:$D$71,S$1)),0)} -> 0.89866633 | ... DX3: {=IFERROR(DW3*(1-INDEX($D3:$D$71,DX$1)),0)} -> 0 | DZ3: 65 years | EA3: 0.00884 | EB3: 0.00923 | EC3: 0.00942 | ED3: 0.0095 | EE3: 0.00912 | EF3: =AVERAGE(EC3:EE3) -> 0.0093466667 | EG3: =ED3/EC3-1 -> 0.008492569 | EH3: =EE3/ED3-1 -> -0.04
A4: =Payments!K2 -> 0.03 | C4: 66 | D4: =EF4 -> 0.01024 | E4: =-1/2*(LN(1-D3)+LN(1-D4)) -> 0.0098417052 | F4: {=SUMPRODUCT($A$6^($K$1:$DT$1+1),K4:DT4,TRANSPOSE(D4:D117))} -> 0.56473774 | G4: {=SUMPRODUCT($A$6^($K$1:$DT$1),K4:DT4)} -> 14.944004 | H4: =(1-$A$4/$A$9*F4)/$A$15 -> 14.481823 | I4: =G4-(12-1)/2/12-(12^2-1)/12/12^2*(E4+LN(1+$A$4)) -> 14.48241 | K4: 1 | L4: {=IFERROR(K4*(1-INDEX($D4:$D$71,L$1)),0)} -> 0.98976 | M4: {=IFERROR(L4*(1-INDEX($D4:$D$71,M$1)),0)} -> 0.9786417 | N4: {=IFERROR(M4*(1-INDEX($D4:$D$71,N$1)),0)} -> 0.96657504 | O4: {=IFERROR(N4*(1-INDEX($D4:$D$71,O$1)),0)} -> 0.95348117 | P4: {=IFERROR(O4*(1-INDEX($D4:$D$71,P$1)),0)} -> 0.93926795 | Q4: {=IFERROR(P4*(1-INDEX($D4:$D$71,Q$1)),0)} -> 0.92385456 | R4: {=IFERROR(Q4*(1-INDEX($D4:$D$71,R$1)),0)} -> 0.90714511 | S4: {=IFERROR(R4*(1-INDEX($D4:$D$71,S$1)),0)} -> 0.88903849 | ... DX4: {=IFERROR(DW4*(1-INDEX($D4:$D$71,DX$1)),0)} -> 0 | DZ4: 66 years | EA4: 0.00972 | EB4: 0.01012 | EC4: 0.01031 | ED4: 0.01042 | EE4: 0.00999 | EF4: =AVERAGE(EC4:EE4) -> 0.01024 | EG4: =ED4/EC4-1 -> 0.010669253 | EH4: =EE4/ED4-1 -> -0.041266795
A5: v | C5: 67 | D5: =EF5 -> 0.011233333 | E5: =-1/2*(LN(1-D4)+LN(1-D5)) -> 0.010794847 | F5: {=SUMPRODUCT($A$6^($K$1:$DT$1+1),K5:DT5,TRANSPOSE(D5:D118))} -> 0.57735196 | G5: {=SUMPRODUCT($A$6^($K$1:$DT$1),K5:DT5)} -> 14.510916 | H5: =(1-$A$4/$A$9*F5)/$A$15 -> 14.048703 | I5: =G5-(12-1)/2/12-(12^2-1)/12/12^2*(E5+LN(1+$A$4)) -> 14.049243 | K5: 1 | L5: {=IFERROR(K5*(1-INDEX($D5:$D$71,L$1)),0)} -> 0.98876667 | M5: {=IFERROR(L5*(1-INDEX($D5:$D$71,M$1)),0)} -> 0.97657517 | N5: {=IFERROR(M5*(1-INDEX($D5:$D$71,N$1)),0)} -> 0.96334584 | O5: {=IFERROR(N5*(1-INDEX($D5:$D$71,O$1)),0)} -> 0.94898556 | P5: {=IFERROR(O5*(1-INDEX($D5:$D$71,P$1)),0)} -> 0.93341271 | Q5: {=IFERROR(P5*(1-INDEX($D5:$D$71,Q$1)),0)} -> 0.91653038 | R5: {=IFERROR(Q5*(1-INDEX($D5:$D$71,R$1)),0)} -> 0.89823644 | S5: {=IFERROR(R5*(1-INDEX($D5:$D$71,S$1)),0)} -> 0.87843631 | ... DX5: {=IFERROR(DW5*(1-INDEX($D5:$D$71,DX$1)),0)} -> 0 | DZ5: 67 years | EA5: 0.0107 | EB5: 0.01111 | EC5: 0.0113 | ED5: 0.01144 | EE5: 0.01096 | EF5: =AVERAGE(EC5:EE5) -> 0.011233333 | EG5: =ED5/EC5-1 -> 0.012389381 | EH5: =EE5/ED5-1 -> -0.041958042
A6: =(1+A4)^-1 -> 0.97087379 | C6: 68 | D6: =EF6 -> 0.01233 | E6: =-1/2*(LN(1-D5)+LN(1-D6)) -> 0.011851774 | F6: {=SUMPRODUCT($A$6^($K$1:$DT$1+1),K6:DT6,TRANSPOSE(D6:D119))} -> 0.59006761 | G6: {=SUMPRODUCT($A$6^($K$1:$DT$1),K6:DT6)} -> 14.074345 | H6: =(1-$A$4/$A$9*F6)/$A$15 -> 13.612101 | I6: =G6-(12-1)/2/12-(12^2-1)/12/12^2*(E6+LN(1+$A$4)) -> 13.612585 | K6: 1 | L6: {=IFERROR(K6*(1-INDEX($D6:$D$71,L$1)),0)} -> 0.98767 | M6: {=IFERROR(L6*(1-INDEX($D6:$D$71,M$1)),0)} -> 0.97429036 | N6: {=IFERROR(M6*(1-INDEX($D6:$D$71,N$1)),0)} -> 0.95976694 | O6: {=IFERROR(N6*(1-INDEX($D6:$D$71,O$1)),0)} -> 0.94401717 | P6: {=IFERROR(O6*(1-INDEX($D6:$D$71,P$1)),0)} -> 0.92694304 | Q6: {=IFERROR(P6*(1-INDEX($D6:$D$71,Q$1)),0)} -> 0.90844126 | R6: {=IFERROR(Q6*(1-INDEX($D6:$D$71,R$1)),0)} -> 0.88841619 | S6: {=IFERROR(R6*(1-INDEX($D6:$D$71,S$1)),0)} -> 0.86676548 | ... DX6: {=IFERROR(DW6*(1-INDEX($D6:$D$71,DX$1)),0)} -> 0 | DZ6: 68 years | EA6: 0.01179 | EB6: 0.01221 | EC6: 0.01239 | ED6: 0.01257 | EE6: 0.01203 | EF6: =AVERAGE(EC6:EE6) -> 0.01233 | EG6: =ED6/EC6-1 -> 0.014527845 | EH6: =EE6/ED6-1 -> -0.042959427
C7: 69 | D7: =EF7 -> 0.013546667 | E7: =-1/2*(LN(1-D6)+LN(1-D7)) -> 0.013022953 | F7: {=SUMPRODUCT($A$6^($K$1:$DT$1+1),K7:DT7,TRANSPOSE(D7:D120))} -> 0.60287306 | G7: {=SUMPRODUCT($A$6^($K$1:$DT$1),K7:DT7)} -> 13.634691 | H7: =(1-$A$4/$A$9*F7)/$A$15 -> 13.172415 | I7: =G7-(12-1)/2/12-(12^2-1)/12/12^2*(E7+LN(1+$A$4)) -> 13.172834 | K7: 1 | L7: {=IFERROR(K7*(1-INDEX($D7:$D$71,L$1)),0)} -> 0.98645333 | M7: {=IFERROR(L7*(1-INDEX($D7:$D$71,M$1)),0)} -> 0.9717486 | N7: {=IFERROR(M7*(1-INDEX($D7:$D$71,N$1)),0)} -> 0.95580221 | O7: {=IFERROR(N7*(1-INDEX($D7:$D$71,O$1)),0)} -> 0.93851493 | P7: {=IFERROR(O7*(1-INDEX($D7:$D$71,P$1)),0)} -> 0.91978217 | Q7: {=IFERROR(P7*(1-INDEX($D7:$D$71,Q$1)),0)} -> 0.89950711 | R7: {=IFERROR(Q7*(1-INDEX($D7:$D$71,R$1)),0)} -> 0.87758612 | S7: {=IFERROR(R7*(1-INDEX($D7:$D$71,S$1)),0)} -> 0.8539147 | ... DX7: {=IFERROR(DW7*(1-INDEX($D7:$D$71,DX$1)),0)} -> 0 | DZ7: 69 years | EA7: 0.01299 | EB7: 0.01344 | EC7: 0.01361 | ED7: 0.01382 | EE7: 0.01321 | EF7: =AVERAGE(EC7:EE7) -> 0.013546667 | EG7: =ED7/EC7-1 -> 0.015429831 | EH7: =EE7/ED7-1 -> -0.044138929
A8: i_12 | C8: 70 | D8: =EF8 -> 0.014906667 | E8: =-1/2*(LN(1-D7)+LN(1-D8)) -> 0.014329074 | F8: {=SUMPRODUCT($A$6^($K$1:$DT$1+1),K8:DT8,TRANSPOSE(D8:D121))} -> 0.615754 | G8: {=SUMPRODUCT($A$6^($K$1:$DT$1),K8:DT8)} -> 13.192446 | H8: =(1-$A$4/$A$9*F8)/$A$15 -> 12.730138 | I8: =G8-(12-1)/2/12-(12^2-1)/12/12^2*(E8+LN(1+$A$4)) -> 12.730481 | K8: 1 | L8: {=IFERROR(K8*(1-INDEX($D8:$D$71,L$1)),0)} -> 0.98509333 | M8: {=IFERROR(L8*(1-INDEX($D8:$D$71,M$1)),0)} -> 0.96892795 | N8: {=IFERROR(M8*(1-INDEX($D8:$D$71,N$1)),0)} -> 0.95140327 | O8: {=IFERROR(N8*(1-INDEX($D8:$D$71,O$1)),0)} -> 0.93241327 | P8: {=IFERROR(O8*(1-INDEX($D8:$D$71,P$1)),0)} -> 0.91185977 | Q8: {=IFERROR(P8*(1-INDEX($D8:$D$71,Q$1)),0)} -> 0.88963775 | R8: {=IFERROR(Q8*(1-INDEX($D8:$D$71,R$1)),0)} -> 0.86564125 | S8: {=IFERROR(R8*(1-INDEX($D8:$D$71,S$1)),0)} -> 0.839773 | ... DX8: {=IFERROR(DW8*(1-INDEX($D8:$D$71,DX$1)),0)} -> 0 | DZ8: 70 years | EA8: 0.01433 | EB8: 0.0148 | EC8: 0.01496 | ED8: 0.01522 | EE8: 0.01454 | EF8: =AVERAGE(EC8:EE8) -> 0.014906667 | EG8: =ED8/EC8-1 -> 0.017379679 | EH8: =EE8/ED8-1 -> -0.044678055
A9: =12*((1+A4)^(1/12)-1) -> 0.029595237 | C9: 71 | D9: =EF9 -> 0.01641 | E9: =-1/2*(LN(1-D8)+LN(1-D9)) -> 0.015782512 | F9: {=SUMPRODUCT($A$6^($K$1:$DT$1+1),K9:DT9,TRANSPOSE(D9:D122))} -> 0.62869165 | G9: {=SUMPRODUCT($A$6^($K$1:$DT$1),K9:DT9)} -> 12.748253 | H9: =(1-$A$4/$A$9*F9)/$A$15 -> 12.285913 | I9: =G9-(12-1)/2/12-(12^2-1)/12/12^2*(E9+LN(1+$A$4)) -> 12.286168 | K9: 1 | L9: {=IFERROR(K9*(1-INDEX($D9:$D$71,L$1)),0)} -> 0.98359 | M9: {=IFERROR(L9*(1-INDEX($D9:$D$71,M$1)),0)} -> 0.96580014 | N9: {=IFERROR(M9*(1-INDEX($D9:$D$71,N$1)),0)} -> 0.94652276 | O9: {=IFERROR(N9*(1-INDEX($D9:$D$71,O$1)),0)} -> 0.92565825 | P9: {=IFERROR(O9*(1-INDEX($D9:$D$71,P$1)),0)} -> 0.90309996 | Q9: {=IFERROR(P9*(1-INDEX($D9:$D$71,Q$1)),0)} -> 0.87874034 | R9: {=IFERROR(Q9*(1-INDEX($D9:$D$71,R$1)),0)} -> 0.85248065 | S9: {=IFERROR(R9*(1-INDEX($D9:$D$71,S$1)),0)} -> 0.82423228 | ... DX9: {=IFERROR(DW9*(1-INDEX($D9:$D$71,DX$1)),0)} -> 0 | DZ9: 71 years | EA9: 0.01583 | EB9: 0.01631 | EC9: 0.01645 | ED9: 0.01677 | EE9: 0.01601 | EF9: =AVERAGE(EC9:EE9) -> 0.01641 | EG9: =ED9/EC9-1 -> 0.019452888 | EH9: =EE9/ED9-1 -> -0.045319022
C10: 72 | D10: =EF10 -> 0.018086667 | E10: =-1/2*(LN(1-D9)+LN(1-D10)) -> 0.017399183 | F10: {=SUMPRODUCT($A$6^($K$1:$DT$1+1),K10:DT10,TRANSPOSE(D10:D123))} -> 0.64167224 | G10: {=SUMPRODUCT($A$6^($K$1:$DT$1),K10:DT10)} -> 12.302586 | H10: =(1-$A$4/$A$9*F10)/$A$15 -> 11.840214 | I10: =G10-(12-1)/2/12-(12^2-1)/12/12^2*(E10+LN(1+$A$4)) -> 11.840367 | K10: 1 | L10: {=IFERROR(K10*(1-INDEX($D10:$D$71,L$1)),0)} -> 0.98191333 | M10: {=IFERROR(L10*(1-INDEX($D10:$D$71,M$1)),0)} -> 0.96231434 | N10: {=IFERROR(M10*(1-INDEX($D10:$D$71,N$1)),0)} -> 0.94110173 | O10: {=IFERROR(N10*(1-INDEX($D10:$D$71,O$1)),0)} -> 0.91816708 | P10: {=IFERROR(O10*(1-INDEX($D10:$D$71,P$1)),0)} -> 0.89340105 | Q10: {=IFERROR(P10*(1-INDEX($D10:$D$71,Q$1)),0)} -> 0.86670325 | R10: {=IFERROR(Q10*(1-INDEX($D10:$D$71,R$1)),0)} -> 0.83798359 | S10: {=IFERROR(R10*(1-INDEX($D10:$D$71,S$1)),0)} -> 0.80715976 | ... DX10: {=IFERROR(DW10*(1-INDEX($D10:$D$71,DX$1)),0)} -> 0 | DZ10: 72 years | EA10: 0.01749 | EB10: 0.018 | EC10: 0.01812 | ED10: 0.0185 | EE10: 0.01764 | EF10: =AVERAGE(EC10:EE10) -> 0.018086667 | EG10: =ED10/EC10-1 -> 0.020971302 | EH10: =EE10/ED10-1 -> -0.046486486
A11: d | C11: 73 | D11: =EF11 -> 0.01996 | E11: =-1/2*(LN(1-D10)+LN(1-D11)) -> 0.019207061 | F11: {=SUMPRODUCT($A$6^($K$1:$DT$1+1),K11:DT11,TRANSPOSE(D11:D124))} -> 0.65467666 | G11: {=SUMPRODUCT($A$6^($K$1:$DT$1),K11:DT11)} -> 11.856101 | H11: =(1-$A$4/$A$9*F11)/$A$15 -> 11.393697 | I11: =G11-(12-1)/2/12-(12^2-1)/12/12^2*(E11+LN(1+$A$4)) -> 11.393732 | K11: 1 | L11: {=IFERROR(K11*(1-INDEX($D11:$D$71,L$1)),0)} -> 0.98004 | M11: {=IFERROR(L11*(1-INDEX($D11:$D$71,M$1)),0)} -> 0.95843665 | N11: {=IFERROR(M11*(1-INDEX($D11:$D$71,N$1)),0)} -> 0.93507955 | O11: {=IFERROR(N11*(1-INDEX($D11:$D$71,O$1)),0)} -> 0.90985734 | P11: {=IFERROR(O11*(1-INDEX($D11:$D$71,P$1)),0)} -> 0.88266777 | Q11: {=IFERROR(P11*(1-INDEX($D11:$D$71,Q$1)),0)} -> 0.8534191 | R11: {=IFERROR(Q11*(1-INDEX($D11:$D$71,R$1)),0)} -> 0.8220275 | S11: {=IFERROR(R11*(1-INDEX($D11:$D$71,S$1)),0)} -> 0.78842576 | ... DX11: {=IFERROR(DW11*(1-INDEX($D11:$D$71,DX$1)),0)} -> 0 | DZ11: 73 years | EA11: 0.01934 | EB11: 0.01989 | EC11: 0.01997 | ED11: 0.02044 | EE11: 0.01947 | EF11: =AVERAGE(EC11:EE11) -> 0.01996 | EG11: =ED11/EC11-1 -> 0.023535303 | EH11: =EE11/ED11-1 -> -0.047455969
A12: =1-1/(1+A4) -> 0.029126214 | C12: 74 | D12: =EF12 -> 0.022043333 | E12: =-1/2*(LN(1-D11)+LN(1-D12)) -> 0.021225905 | F12: {=SUMPRODUCT($A$6^($K$1:$DT$1+1),K12:DT12,TRANSPOSE(D12:D125))} -> 0.66768393 | G12: {=SUMPRODUCT($A$6^($K$1:$DT$1),K12:DT12)} -> 11.409518 | H12: =(1-$A$4/$A$9*F12)/$A$15 -> 10.947081 | I12: =G12-(12-1)/2/12-(12^2-1)/12/12^2*(E12+LN(1+$A$4)) -> 10.946982 | K12: 1 | L12: {=IFERROR(K12*(1-INDEX($D12:$D$71,L$1)),0)} -> 0.97795667 | M12: {=IFERROR(L12*(1-INDEX($D12:$D$71,M$1)),0)} -> 0.95412386 | N12: {=IFERROR(M12*(1-INDEX($D12:$D$71,N$1)),0)} -> 0.92838796 | O12: {=IFERROR(N12*(1-INDEX($D12:$D$71,O$1)),0)} -> 0.90064463 | P12: {=IFERROR(O12*(1-INDEX($D12:$D$71,P$1)),0)} -> 0.87080027 | Q12: {=IFERROR(P12*(1-INDEX($D12:$D$71,Q$1)),0)} -> 0.83876934 | R12: {=IFERROR(Q12*(1-INDEX($D12:$D$71,R$1)),0)} -> 0.80448324 | S12: {=IFERROR(R12*(1-INDEX($D12:$D$71,S$1)),0)} -> 0.76790339 | ... DX12: {=IFERROR(DW12*(1-INDEX($D12:$D$71,DX$1)),0)} -> 0 | DZ12: 74 years | EA12: 0.02141 | EB12: 0.022 | EC12: 0.02203 | ED12: 0.02259 | EE12: 0.02151 | EF12: =AVERAGE(EC12:EE12) -> 0.022043333 | EG12: =ED12/EC12-1 -> 0.025419882 | EH12: =EE12/ED12-1 -> -0.047808765
C13: 75 | D13: =EF13 -> 0.02437 | E13: =-1/2*(LN(1-D12)+LN(1-D13)) -> 0.02348089 | F13: {=SUMPRODUCT($A$6^($K$1:$DT$1+1),K13:DT13,TRANSPOSE(D13:D126))} -> 0.68067548 | G13: {=SUMPRODUCT($A$6^($K$1:$DT$1),K13:DT13)} -> 10.963475 | H13: =(1-$A$4/$A$9*F13)/$A$15 -> 10.501006 | I13: =G13-(12-1)/2/12-(12^2-1)/12/12^2*(E13+LN(1+$A$4)) -> 10.500753 | K13: 1 | L13: {=IFERROR(K13*(1-INDEX($D13:$D$71,L$1)),0)} -> 0.97563 | M13: {=IFERROR(L13*(1-INDEX($D13:$D$71,M$1)),0)} -> 0.94931401 | N13: {=IFERROR(M13*(1-INDEX($D13:$D$71,N$1)),0)} -> 0.92094534 | O13: {=IFERROR(N13*(1-INDEX($D13:$D$71,O$1)),0)} -> 0.89042828 | P13: {=IFERROR(O13*(1-INDEX($D13:$D$71,P$1)),0)} -> 0.85767536 | Q13: {=IFERROR(P13*(1-INDEX($D13:$D$71,Q$1)),0)} -> 0.82261645 | R13: {=IFERROR(Q13*(1-INDEX($D13:$D$71,R$1)),0)} -> 0.78521208 | S13: {=IFERROR(R13*(1-INDEX($D13:$D$71,S$1)),0)} -> 0.74545941 | ... DX13: {=IFERROR(DW13*(1-INDEX($D13:$D$71,DX$1)),0)} -> 0 | DZ13: 75 years | EA13: 0.02371 | EB13: 0.02435 | EC13: 0.02433 | ED13: 0.025 | EE13: 0.02378 | EF13: =AVERAGE(EC13:EE13) -> 0.02437 | EG13: =ED13/EC13-1 -> 0.027538019 | EH13: =EE13/ED13-1 -> -0.0488
A14: d_12 | C14: 76 | D14: =EF14 -> 0.026973333 | E14: =-1/2*(LN(1-D13)+LN(1-D14)) -> 0.026007827 | F14: {=SUMPRODUCT($A$6^($K$1:$DT$1+1),K14:DT14,TRANSPOSE(D14:D127))} -> 0.69362949 | G14: {=SUMPRODUCT($A$6^($K$1:$DT$1),K14:DT14)} -> 10.518721 | H14: =(1-$A$4/$A$9*F14)/$A$15 -> 10.056219 | I14: =G14-(12-1)/2/12-(12^2-1)/12/12^2*(E14+LN(1+$A$4)) -> 10.055789 | K14: 1 | L14: {=IFERROR(K14*(1-INDEX($D14:$D$71,L$1)),0)} -> 0.97302667 | M14: {=IFERROR(L14*(1-INDEX($D14:$D$71,M$1)),0)} -> 0.94394939 | N14: {=IFERROR(M14*(1-INDEX($D14:$D$71,N$1)),0)} -> 0.91267005 | O14: {=IFERROR(N14*(1-INDEX($D14:$D$71,O$1)),0)} -> 0.879099 | P14: {=IFERROR(O14*(1-INDEX($D14:$D$71,P$1)),0)} -> 0.84316437 | Q14: {=IFERROR(P14*(1-INDEX($D14:$D$71,Q$1)),0)} -> 0.80482568 | R14: {=IFERROR(Q14*(1-INDEX($D14:$D$71,R$1)),0)} -> 0.76408004 | S14: {=IFERROR(R14*(1-INDEX($D14:$D$71,S$1)),0)} -> 0.72096555 | ... DX14: {=IFERROR(DW14*(1-INDEX($D14:$D$71,DX$1)),0)} -> 0 | DZ14: 76 years | EA14: 0.02629 | EB14: 0.02699 | EC14: 0.02689 | ED14: 0.0277 | EE14: 0.02633 | EF14: =AVERAGE(EC14:EE14) -> 0.026973333 | EG14: =ED14/EC14-1 -> 0.030122722 | EH14: =EE14/ED14-1 -> -0.049458484
A15: =(1-(1+A4)^(-1/12))*12 -> 0.029522427 | C15: 77 | D15: =EF15 -> 0.029883333 | E15: =-1/2*(LN(1-D14)+LN(1-D15)) -> 0.028841365 | F15: {=SUMPRODUCT($A$6^($K$1:$DT$1+1),K15:DT15,TRANSPOSE(D15:D128))} -> 0.7065223 | G15: {=SUMPRODUCT($A$6^($K$1:$DT$1),K15:DT15)} -> 10.076068 | H15: =(1-$A$4/$A$9*F15)/$A$15 -> 9.6135342 | I15: =G15-(12-1)/2/12-(12^2-1)/12/12^2*(E15+LN(1+$A$4)) -> 9.6129014 | K15: 1 | L15: {=IFERROR(K15*(1-INDEX($D15:$D$71,L$1)),0)} -> 0.97011667 | M15: {=IFERROR(L15*(1-INDEX($D15:$D$71,M$1)),0)} -> 0.93797023 | N15: {=IFERROR(M15*(1-INDEX($D15:$D$71,N$1)),0)} -> 0.90346856 | O15: {=IFERROR(N15*(1-INDEX($D15:$D$71,O$1)),0)} -> 0.86653778 | P15: {=IFERROR(O15*(1-INDEX($D15:$D$71,P$1)),0)} -> 0.82713631 | Q15: {=IFERROR(P15*(1-INDEX($D15:$D$71,Q$1)),0)} -> 0.78526115 | R15: {=IFERROR(Q15*(1-INDEX($D15:$D$71,R$1)),0)} -> 0.74095148 | S15: {=IFERROR(R15*(1-INDEX($D15:$D$71,S$1)),0)} -> 0.69430365 | ... DX15: {=IFERROR(DW15*(1-INDEX($D15:$D$71,DX$1)),0)} -> 0 | DZ15: 77 years | EA15: 0.02917 | EB15: 0.02995 | EC15: 0.02975 | ED15: 0.03072 | EE15: 0.02918 | EF15: =AVERAGE(EC15:EE15) -> 0.029883333 | EG15: =ED15/EC15-1 -> 0.032605042 | EH15: =EE15/ED15-1 -> -0.050130208
C16: 78 | D16: =EF16 -> 0.033136667 | E16: =-1/2*(LN(1-D15)+LN(1-D16)) -> 0.032018532 | F16: {=SUMPRODUCT($A$6^($K$1:$DT$1+1),K16:DT16,TRANSPOSE(D16:D129))} -> 0.71933064 | G16: {=SUMPRODUCT($A$6^($K$1:$DT$1),K16:DT16)} -> 9.6363148 | H16: =(1-$A$4/$A$9*F16)/$A$15 -> 9.1737496 | I16: =G16-(12-1)/2/12-(12^2-1)/12/12^2*(E16+LN(1+$A$4)) -> 9.1728857 | K16: 1 | L16: {=IFERROR(K16*(1-INDEX($D16:$D$71,L$1)),0)} -> 0.96686333 | M16: {=IFERROR(L16*(1-INDEX($D16:$D$71,M$1)),0)} -> 0.93129888 | N16: {=IFERROR(M16*(1-INDEX($D16:$D$71,N$1)),0)} -> 0.89323048 | O16: {=IFERROR(N16*(1-INDEX($D16:$D$71,O$1)),0)} -> 0.85261529 | P16: {=IFERROR(O16*(1-INDEX($D16:$D$71,P$1)),0)} -> 0.80945022 | Q16: {=IFERROR(P16*(1-INDEX($D16:$D$71,Q$1)),0)} -> 0.76377565 | R16: {=IFERROR(Q16*(1-INDEX($D16:$D$71,R$1)),0)} -> 0.71569088 | S16: {=IFERROR(R16*(1-INDEX($D16:$D$71,S$1)),0)} -> 0.66536588 | ... DX16: {=IFERROR(DW16*(1-INDEX($D16:$D$71,DX$1)),0)} -> 0 | DZ16: 78 years | EA16: 0.03239 | EB16: 0.03326 | EC16: 0.03294 | ED16: 0.0341 | EE16: 0.03237 | EF16: =AVERAGE(EC16:EE16) -> 0.033136667 | EG16: =ED16/EC16-1 -> 0.035215543 | EH16: =EE16/ED16-1 -> -0.050733138
C17: 79 | D17: =EF17 -> 0.036783333 | E17: =-1/2*(LN(1-D16)+LN(1-D17)) -> 0.035587513 | F17: {=SUMPRODUCT($A$6^($K$1:$DT$1+1),K17:DT17,TRANSPOSE(D17:D130))} -> 0.73203095 | G17: {=SUMPRODUCT($A$6^($K$1:$DT$1),K17:DT17)} -> 9.2002705 | H17: =(1-$A$4/$A$9*F17)/$A$15 -> 8.7376738 | I17: =G17-(12-1)/2/12-(12^2-1)/12/12^2*(E17+LN(1+$A$4)) -> 8.7365461 | K17: 1 | L17: {=IFERROR(K17*(1-INDEX($D17:$D$71,L$1)),0)} -> 0.96321667 | M17: {=IFERROR(L17*(1-INDEX($D17:$D$71,M$1)),0)} -> 0.92384358 | N17: {=IFERROR(M17*(1-INDEX($D17:$D$71,N$1)),0)} -> 0.88183641 | O17: {=IFERROR(N17*(1-INDEX($D17:$D$71,O$1)),0)} -> 0.83719197 | P17: {=IFERROR(O17*(1-INDEX($D17:$D$71,P$1)),0)} -> 0.78995202 | Q17: {=IFERROR(P17*(1-INDEX($D17:$D$71,Q$1)),0)} -> 0.74021928 | R17: {=IFERROR(Q17*(1-INDEX($D17:$D$71,R$1)),0)} -> 0.68816952 | S17: {=IFERROR(R17*(1-INDEX($D17:$D$71,S$1)),0)} -> 0.63407252 | ... DX17: {=IFERROR(DW17*(1-INDEX($D17:$D$71,DX$1)),0)} -> 0 | DZ17: 79 years | EA17: 0.03599 | EB17: 0.03698 | EC17: 0.03651 | ED17: 0.0379 | EE17: 0.03594 | EF17: =AVERAGE(EC17:EE17) -> 0.036783333 | EG17: =ED17/EC17-1 -> 0.038071761 | EH17: =EE17/ED17-1 -> -0.05171504
C18: 80 | D18: =EF18 -> 0.040876667 | E18: =-1/2*(LN(1-D17)+LN(1-D18)) -> 0.039606254 | F18: {=SUMPRODUCT($A$6^($K$1:$DT$1+1),K18:DT18,TRANSPOSE(D18:D131))} -> 0.74459732 | G18: {=SUMPRODUCT($A$6^($K$1:$DT$1),K18:DT18)} -> 8.7688253 | H18: =(1-$A$4/$A$9*F18)/$A$15 -> 8.3061974 | I18: =G18-(12-1)/2/12-(12^2-1)/12/12^2*(E18+LN(1+$A$4)) -> 8.3047682 | K18: 1 | L18: {=IFERROR(K18*(1-INDEX($D18:$D$71,L$1)),0)} -> 0.95912333 | M18: {=IFERROR(L18*(1-INDEX($D18:$D$71,M$1)),0)} -> 0.915512 | N18: {=IFERROR(M18*(1-INDEX($D18:$D$71,N$1)),0)} -> 0.86916267 | O18: {=IFERROR(N18*(1-INDEX($D18:$D$71,O$1)),0)} -> 0.82011872 | P18: {=IFERROR(O18*(1-INDEX($D18:$D$71,P$1)),0)} -> 0.76848678 | Q18: {=IFERROR(P18*(1-INDEX($D18:$D$71,Q$1)),0)} -> 0.71444935 | R18: {=IFERROR(Q18*(1-INDEX($D18:$D$71,R$1)),0)} -> 0.65828649 | S18: {=IFERROR(R18*(1-INDEX($D18:$D$71,S$1)),0)} -> 0.60037264 | ... DX18: {=IFERROR(DW18*(1-INDEX($D18:$D$71,DX$1)),0)} -> 0 | DZ18: 80 years | EA18: 0.04003 | EB18: 0.04116 | EC18: 0.04051 | ED18: 0.04216 | EE18: 0.03996 | EF18: =AVERAGE(EC18:EE18) -> 0.040876667 | EG18: =ED18/EC18-1 -> 0.040730684 | EH18: =EE18/ED18-1 -> -0.052182163
C19: 81 | D19: =EF19 -> 0.04547 | E19: =-1/2*(LN(1-D18)+LN(1-D19)) -> 0.044135906 | F19: {=SUMPRODUCT($A$6^($K$1:$DT$1+1),K19:DT19,TRANSPOSE(D19:D132))} -> 0.75700231 | G19: {=SUMPRODUCT($A$6^($K$1:$DT$1),K19:DT19)} -> 8.3429208 | H19: =(1-$A$4/$A$9*F19)/$A$15 -> 7.8802621 | I19: =G19-(12-1)/2/12-(12^2-1)/12/12^2*(E19+LN(1+$A$4)) -> 7.8784889 | K19: 1 | L19: {=IFERROR(K19*(1-INDEX($D19:$D$71,L$1)),0)} -> 0.95453 | M19: {=IFERROR(L19*(1-INDEX($D19:$D$71,M$1)),0)} -> 0.90620533 | N19: {=IFERROR(M19*(1-INDEX($D19:$D$71,N$1)),0)} -> 0.85507118 | O19: {=IFERROR(N19*(1-INDEX($D19:$D$71,O$1)),0)} -> 0.80123875 | P19: {=IFERROR(O19*(1-INDEX($D19:$D$71,P$1)),0)} -> 0.74489831 | Q19: {=IFERROR(P19*(1-INDEX($D19:$D$71,Q$1)),0)} -> 0.68634186 | R19: {=IFERROR(Q19*(1-INDEX($D19:$D$71,R$1)),0)} -> 0.62595979 | S19: {=IFERROR(R19*(1-INDEX($D19:$D$71,S$1)),0)} -> 0.56426936 | ... DX19: {=IFERROR(DW19*(1-INDEX($D19:$D$71,DX$1)),0)} -> 0 | DZ19: 81 years | EA19: 0.04456 | EB19: 0.04585 | EC19: 0.04499 | ED19: 0.04695 | EE19: 0.04447 | EF19: =AVERAGE(EC19:EE19) -> 0.04547 | EG19: =ED19/EC19-1 -> 0.043565237 | EH19: =EE19/ED19-1 -> -0.052822151
C20: 82 | D20: =EF20 -> 0.050626667 | E20: =-1/2*(LN(1-D19)+LN(1-D20)) -> 0.049244684 | F20: {=SUMPRODUCT($A$6^($K$1:$DT$1+1),K20:DT20,TRANSPOSE(D20:D133))} -> 0.76921875 | G20: {=SUMPRODUCT($A$6^($K$1:$DT$1),K20:DT20)} -> 7.9234895 | H20: =(1-$A$4/$A$9*F20)/$A$15 -> 7.4608005 | I20: =G20-(12-1)/2/12-(12^2-1)/12/12^2*(E20+LN(1+$A$4)) -> 7.4586348 | K20: 1 | L20: {=IFERROR(K20*(1-INDEX($D20:$D$71,L$1)),0)} -> 0.94937333 | M20: {=IFERROR(L20*(1-INDEX($D20:$D$71,M$1)),0)} -> 0.89580336 | N20: {=IFERROR(M20*(1-INDEX($D20:$D$71,N$1)),0)} -> 0.83940657 | O20: {=IFERROR(N20*(1-INDEX($D20:$D$71,O$1)),0)} -> 0.7803823 | P20: {=IFERROR(O20*(1-INDEX($D20:$D$71,P$1)),0)} -> 0.71903644 | Q20: {=IFERROR(P20*(1-INDEX($D20:$D$71,Q$1)),0)} -> 0.65577801 | R20: {=IFERROR(Q20*(1-INDEX($D20:$D$71,R$1)),0)} -> 0.5911489 | S20: {=IFERROR(R20*(1-INDEX($D20:$D$71,S$1)),0)} -> 0.52581513 | ... DX20: {=IFERROR(DW20*(1-INDEX($D20:$D$71,DX$1)),0)} -> 0 | DZ20: 82 years | EA20: 0.04964 | EB20: 0.05114 | EC20: 0.05001 | ED20: 0.05233 | EE20: 0.04954 | EF20: =AVERAGE(EC20:EE20) -> 0.050626667 | EG20: =ED20/EC20-1 -> 0.046390722 | EH20: =EE20/ED20-1 -> -0.053315498
C21: 83 | D21: =EF21 -> 0.056426667 | E21: =-1/2*(LN(1-D20)+LN(1-D21)) -> 0.055017177 | F21: {=SUMPRODUCT($A$6^($K$1:$DT$1+1),K21:DT21,TRANSPOSE(D21:D134))} -> 0.78121917 | G21: {=SUMPRODUCT($A$6^($K$1:$DT$1),K21:DT21)} -> 7.5114752 | H21: =(1-$A$4/$A$9*F21)/$A$15 -> 7.0487563 | I21: =G21-(12-1)/2/12-(12^2-1)/12/12^2*(E21+LN(1+$A$4)) -> 7.0461428 | K21: 1 | L21: {=IFERROR(K21*(1-INDEX($D21:$D$71,L$1)),0)} -> 0.94357333 | M21: {=IFERROR(L21*(1-INDEX($D21:$D$71,M$1)),0)} -> 0.8841691 | N21: {=IFERROR(M21*(1-INDEX($D21:$D$71,N$1)),0)} -> 0.82199728 | O21: {=IFERROR(N21*(1-INDEX($D21:$D$71,O$1)),0)} -> 0.75738007 | P21: {=IFERROR(O21*(1-INDEX($D21:$D$71,P$1)),0)} -> 0.6907483 | Q21: {=IFERROR(P21*(1-INDEX($D21:$D$71,Q$1)),0)} -> 0.62267275 | R21: {=IFERROR(Q21*(1-INDEX($D21:$D$71,R$1)),0)} -> 0.55385496 | S21: {=IFERROR(R21*(1-INDEX($D21:$D$71,S$1)),0)} -> 0.48514371 | ... DX21: {=IFERROR(DW21*(1-INDEX($D21:$D$71,DX$1)),0)} -> 0 | DZ21: 83 years | EA21: 0.05535 | EB21: 0.0571 | EC21: 0.05564 | ED21: 0.05839 | EE21: 0.05525 | EF21: =AVERAGE(EC21:EE21) -> 0.056426667 | EG21: =ED21/EC21-1 -> 0.049424874 | EH21: =EE21/ED21-1 -> -0.053776332
C22: 84 | D22: =EF22 -> 0.062956667 | E22: =-1/2*(LN(1-D21)+LN(1-D22)) -> 0.061553472 | F22: {=SUMPRODUCT($A$6^($K$1:$DT$1+1),K22:DT22,TRANSPOSE(D22:D135))} -> 0.79297396 | G22: {=SUMPRODUCT($A$6^($K$1:$DT$1),K22:DT22)} -> 7.1078942 | H22: =(1-$A$4/$A$9*F22)/$A$15 -> 6.6451462 | I22: =G22-(12-1)/2/12-(12^2-1)/12/12^2*(E22+LN(1+$A$4)) -> 6.6420209 | K22: 1 | L22: {=IFERROR(K22*(1-INDEX($D22:$D$71,L$1)),0)} -> 0.93704333 | M22: {=IFERROR(L22*(1-INDEX($D22:$D$71,M$1)),0)} -> 0.87115357 | N22: {=IFERROR(M22*(1-INDEX($D22:$D$71,N$1)),0)} -> 0.80267219 | O22: {=IFERROR(N22*(1-INDEX($D22:$D$71,O$1)),0)} -> 0.73205576 | P22: {=IFERROR(O22*(1-INDEX($D22:$D$71,P$1)),0)} -> 0.65990923 | Q22: {=IFERROR(P22*(1-INDEX($D22:$D$71,Q$1)),0)} -> 0.58697606 | R22: {=IFERROR(Q22*(1-INDEX($D22:$D$71,R$1)),0)} -> 0.51415581 | S22: {=IFERROR(R22*(1-INDEX($D22:$D$71,S$1)),0)} -> 0.44267616 | ... DX22: {=IFERROR(DW22*(1-INDEX($D22:$D$71,DX$1)),0)} -> 0 | DZ22: 84 years | EA22: 0.06176 | EB22: 0.06382 | EC22: 0.06196 | ED22: 0.06523 | EE22: 0.06168 | EF22: =AVERAGE(EC22:EE22) -> 0.062956667 | EG22: =ED22/EC22-1 -> 0.052775985 | EH22: =EE22/ED22-1 -> -0.054422812
C23: 85 | D23: =EF23 -> 0.070316667 | E23: =-1/2*(LN(1-D22)+LN(1-D23)) -> 0.068968502 | F23: {=SUMPRODUCT($A$6^($K$1:$DT$1+1),K23:DT23,TRANSPOSE(D23:D136))} -> 0.80445213 | G23: {=SUMPRODUCT($A$6^($K$1:$DT$1),K23:DT23)} -> 6.7138101 | H23: =(1-$A$4/$A$9*F23)/$A$15 -> 6.2510336 | I23: =G23-(12-1)/2/12-(12^2-1)/12/12^2*(E23+LN(1+$A$4)) -> 6.2473232 | K23: 1 | L23: {=IFERROR(K23*(1-INDEX($D23:$D$71,L$1)),0)} -> 0.92968333 | M23: {=IFERROR(L23*(1-INDEX($D23:$D$71,M$1)),0)} -> 0.85660093 | N23: {=IFERROR(M23*(1-INDEX($D23:$D$71,N$1)),0)} -> 0.78124003 | O23: {=IFERROR(N23*(1-INDEX($D23:$D$71,O$1)),0)} -> 0.70424622 | P23: {=IFERROR(O23*(1-INDEX($D23:$D$71,P$1)),0)} -> 0.62641293 | Q23: {=IFERROR(P23*(1-INDEX($D23:$D$71,Q$1)),0)} -> 0.54870014 | R23: {=IFERROR(Q23*(1-INDEX($D23:$D$71,R$1)),0)} -> 0.47241802 | S23: {=IFERROR(R23*(1-INDEX($D23:$D$71,S$1)),0)} -> 0.39914126 | ... DX23: {=IFERROR(DW23*(1-INDEX($D23:$D$71,DX$1)),0)} -> 0 | DZ23: 85 years | EA23: 0.06896 | EB23: 0.0714 | EC23: 0.06907 | ED23: 0.07294 | EE23: 0.06894 | EF23: =AVERAGE(EC23:EE23) -> 0.070316667 | EG23: =ED23/EC23-1 -> 0.056030114 | EH23: =EE23/ED23-1 -> -0.054839594
C24: 86 | D24: =EF24 -> 0.07861 | E24: =-1/2*(LN(1-D23)+LN(1-D24)) -> 0.077391566 | F24: {=SUMPRODUCT($A$6^($K$1:$DT$1+1),K24:DT24,TRANSPOSE(D24:D137))} -> 0.81562076 | G24: {=SUMPRODUCT($A$6^($K$1:$DT$1),K24:DT24)} -> 6.3303538 | H24: =(1-$A$4/$A$9*F24)/$A$15 -> 5.8675496 | I24: =G24-(12-1)/2/12-(12^2-1)/12/12^2*(E24+LN(1+$A$4)) -> 5.8631698 | K24: 1 | L24: {=IFERROR(K24*(1-INDEX($D24:$D$71,L$1)),0)} -> 0.92139 | M24: {=IFERROR(L24*(1-INDEX($D24:$D$71,M$1)),0)} -> 0.84032918 | N24: {=IFERROR(M24*(1-INDEX($D24:$D$71,N$1)),0)} -> 0.75751194 | O24: {=IFERROR(N24*(1-INDEX($D24:$D$71,O$1)),0)} -> 0.67379172 | P24: {=IFERROR(O24*(1-INDEX($D24:$D$71,P$1)),0)} -> 0.59020112 | Q24: {=IFERROR(P24*(1-INDEX($D24:$D$71,Q$1)),0)} -> 0.50814939 | R24: {=IFERROR(Q24*(1-INDEX($D24:$D$71,R$1)),0)} -> 0.42933034 | S24: {=IFERROR(R24*(1-INDEX($D24:$D$71,S$1)),0)} -> 0.35535958 | ... DX24: {=IFERROR(DW24*(1-INDEX($D24:$D$71,DX$1)),0)} -> 0 | DZ24: 86 years | EA24: 0.07708 | EB24: 0.07998 | EC24: 0.07706 | ED24: 0.08164 | EE24: 0.07713 | EF24: =AVERAGE(EC24:EE24) -> 0.07861 | EG24: =ED24/EC24-1 -> 0.059434207 | EH24: =EE24/ED24-1 -> -0.055242528
C25: 87 | D25: =EF25 -> 0.087976667 | E25: =-1/2*(LN(1-D24)+LN(1-D25)) -> 0.086980792 | F25: {=SUMPRODUCT($A$6^($K$1:$DT$1+1),K25:DT25,TRANSPOSE(D25:D138))} -> 0.82644633 | G25: {=SUMPRODUCT($A$6^($K$1:$DT$1),K25:DT25)} -> 5.9586759 | H25: =(1-$A$4/$A$9*F25)/$A$15 -> 5.4958448 | I25: =G25-(12-1)/2/12-(12^2-1)/12/12^2*(E25+LN(1+$A$4)) -> 5.4906984 | K25: 1 | L25: {=IFERROR(K25*(1-INDEX($D25:$D$71,L$1)),0)} -> 0.91202333 | M25: {=IFERROR(L25*(1-INDEX($D25:$D$71,M$1)),0)} -> 0.82214039 | N25: {=IFERROR(M25*(1-INDEX($D25:$D$71,N$1)),0)} -> 0.73127744 | O25: {=IFERROR(N25*(1-INDEX($D25:$D$71,O$1)),0)} -> 0.64055516 | P25: {=IFERROR(O25*(1-INDEX($D25:$D$71,P$1)),0)} -> 0.55150305 | Q25: {=IFERROR(P25*(1-INDEX($D25:$D$71,Q$1)),0)} -> 0.46595941 | R25: {=IFERROR(Q25*(1-INDEX($D25:$D$71,R$1)),0)} -> 0.38567771 | S25: {=IFERROR(R25*(1-INDEX($D25:$D$71,S$1)),0)} -> 0.31219068 | ... DX25: {=IFERROR(DW25*(1-INDEX($D25:$D$71,DX$1)),0)} -> 0 | DZ25: 87 years | EA25: 0.08621 | EB25: 0.08967 | EC25: 0.08606 | ED25: 0.09148 | EE25: 0.08639 | EF25: =AVERAGE(EC25:EE25) -> 0.087976667 | EG25: =ED25/EC25-1 -> 0.062979317 | EH25: =EE25/ED25-1 -> -0.055640577
C26: 88 | D26: =EF26 -> 0.098553333 | E26: =-1/2*(LN(1-D25)+LN(1-D26)) -> 0.097922052 | F26: {=SUMPRODUCT($A$6^($K$1:$DT$1+1),K26:DT26,TRANSPOSE(D26:D139))} -> 0.83688983 | G26: {=SUMPRODUCT($A$6^($K$1:$DT$1),K26:DT26)} -> 5.6001157 | H26: =(1-$A$4/$A$9*F26)/$A$15 -> 5.1372587 | I26: =G26-(12-1)/2/12-(12^2-1)/12/12^2*(E26+LN(1+$A$4)) -> 5.1312328 | K26: 1 | L26: {=IFERROR(K26*(1-INDEX($D26:$D$71,L$1)),0)} -> 0.90144667 | M26: {=IFERROR(L26*(1-INDEX($D26:$D$71,M$1)),0)} -> 0.80181878 | N26: {=IFERROR(M26*(1-INDEX($D26:$D$71,N$1)),0)} -> 0.70234514 | O26: {=IFERROR(N26*(1-INDEX($D26:$D$71,O$1)),0)} -> 0.60470278 | P26: {=IFERROR(O26*(1-INDEX($D26:$D$71,P$1)),0)} -> 0.51090733 | Q26: {=IFERROR(P26*(1-INDEX($D26:$D$71,Q$1)),0)} -> 0.4228814 | R26: {=IFERROR(Q26*(1-INDEX($D26:$D$71,R$1)),0)} -> 0.34230558 | S26: {=IFERROR(R26*(1-INDEX($D26:$D$71,S$1)),0)} -> 0.26972767 | ... DX26: {=IFERROR(DW26*(1-INDEX($D26:$D$71,DX$1)),0)} -> 0 | DZ26: 88 years | EA26: 0.09651 | EB26: 0.10065 | EC26: 0.0962 | ED26: 0.10261 | EE26: 0.09685 | EF26: =AVERAGE(EC26:EE26) -> 0.098553333 | EG26: =ED26/EC26-1 -> 0.066632017 | EH26: =EE26/ED26-1 -> -0.05613488
C27: 89 | D27: =EF27 -> 0.11052 | E27: =-1/2*(LN(1-D26)+LN(1-D27)) -> 0.11043633 | F27: {=SUMPRODUCT($A$6^($K$1:$DT$1+1),K27:DT27,TRANSPOSE(D27:D140))} -> 0.84690889 | G27: {=SUMPRODUCT($A$6^($K$1:$DT$1),K27:DT27)} -> 5.2561282 | H27: =(1-$A$4/$A$9*F27)/$A$15 -> 4.7932463 | I27: =G27-(12-1)/2/12-(12^2-1)/12/12^2*(E27+LN(1+$A$4)) -> 4.7862096 | K27: 1 | L27: {=IFERROR(K27*(1-INDEX($D27:$D$71,L$1)),0)} -> 0.88948 | M27: {=IFERROR(L27*(1-INDEX($D27:$D$71,M$1)),0)} -> 0.77913111 | N27: {=IFERROR(M27*(1-INDEX($D27:$D$71,N$1)),0)} -> 0.67081371 | O27: {=IFERROR(N27*(1-INDEX($D27:$D$71,O$1)),0)} -> 0.56676379 | P27: {=IFERROR(O27*(1-INDEX($D27:$D$71,P$1)),0)} -> 0.46911417 | Q27: {=IFERROR(P27*(1-INDEX($D27:$D$71,Q$1)),0)} -> 0.37972916 | R27: {=IFERROR(Q27*(1-INDEX($D27:$D$71,R$1)),0)} -> 0.29921645 | S27: {=IFERROR(R27*(1-INDEX($D27:$D$71,S$1)),0)} -> 0.22972941 | ... DX27: {=IFERROR(DW27*(1-INDEX($D27:$D$71,DX$1)),0)} -> 0 | DZ27: 89 years | EA27: 0.10812 | EB27: 0.11309 | EC27: 0.10764 | ED27: 0.11521 | EE27: 0.10871 | EF27: =AVERAGE(EC27:EE27) -> 0.11052 | EG27: =ED27/EC27-1 -> 0.070327016 | EH27: =EE27/ED27-1 -> -0.056418714
... C48: 110 | D48: =EF48 -> 1 | E48: =-1/2*(LN(1-D47)+LN(1-D48)) -> #NUM! | F48: {=SUMPRODUCT($A$6^($K$1:$DT$1+1),K48:DT48,TRANSPOSE(D48:D161))} -> 0.97087379 | G48: {=SUMPRODUCT($A$6^($K$1:$DT$1),K48:DT48)} -> 1 | H48: =(1-$A$4/$A$9*F48)/$A$15 -> 0.53681035 | I48: =G48-(12-1)/2/12-(12^2-1)/12/12^2*(E48+LN(1+$A$4)) -> #NUM! | K48: 1 | L48: {=IFERROR(K48*(1-INDEX($D48:$D$71,L$1)),0)} -> 0 | M48: {=IFERROR(L48*(1-INDEX($D48:$D$71,M$1)),0)} -> 0 | N48: {=IFERROR(M48*(1-INDEX($D48:$D$71,N$1)),0)} -> 0 | O48: {=IFERROR(N48*(1-INDEX($D48:$D$71,O$1)),0)} -> 0 | P48: {=IFERROR(O48*(1-INDEX($D48:$D$71,P$1)),0)} -> 0 | Q48: {=IFERROR(P48*(1-INDEX($D48:$D$71,Q$1)),0)} -> 0 | R48: {=IFERROR(Q48*(1-INDEX($D48:$D$71,R$1)),0)} -> 0 | S48: {=IFERROR(R48*(1-INDEX($D48:$D$71,S$1)),0)} -> 0 | ... DX48: {=IFERROR(DW48*(1-INDEX($D48:$D$71,DX$1)),0)} -> 0 | DZ48: 110 years and over | EA48: 1 | EB48: 1 | EC48: 1 | ED48: 1 | EE48: 1 | EF48: =AVERAGE(EC48:EE48) -> 1 | EG48: =ED48/EC48-1 -> 0 | EH48: =EE48/ED48-1 -> 0
C49: 111 | D49: =EF49 -> 0 | E49: =-1/2*(LN(1-D48)+LN(1-D49)) -> #NUM! | F49: {=SUMPRODUCT($A$6^($K$1:$DT$1+1),K49:DT49,TRANSPOSE(D49:D162))} -> 0 | G49: {=SUMPRODUCT($A$6^($K$1:$DT$1),K49:DT49)} -> 17.443608 | H49: =(1-$A$4/$A$9*F49)/$A$15 -> 33.872554 | I49: =G49-(12-1)/2/12-(12^2-1)/12/12^2*(E49+LN(1+$A$4)) -> #NUM! | K49: 1 | L49: {=IFERROR(K49*(1-INDEX($D49:$D$71,L$1)),0)} -> 1 | M49: {=IFERROR(L49*(1-INDEX($D49:$D$71,M$1)),0)} -> 1 | N49: {=IFERROR(M49*(1-INDEX($D49:$D$71,N$1)),0)} -> 1 | O49: {=IFERROR(N49*(1-INDEX($D49:$D$71,O$1)),0)} -> 1 | P49: {=IFERROR(O49*(1-INDEX($D49:$D$71,P$1)),0)} -> 1 | Q49: {=IFERROR(P49*(1-INDEX($D49:$D$71,Q$1)),0)} -> 1 | R49: {=IFERROR(Q49*(1-INDEX($D49:$D$71,R$1)),0)} -> 1 | S49: {=IFERROR(R49*(1-INDEX($D49:$D$71,S$1)),0)} -> 1 | ... DX49: {=IFERROR(DW49*(1-INDEX($D49:$D$71,DX$1)),0)} -> 0
C50: 112 | D50: =EF50 -> 0 | E50: =-1/2*(LN(1-D49)+LN(1-D50)) -> 0 | F50: {=SUMPRODUCT($A$6^($K$1:$DT$1+1),K50:DT50,TRANSPOSE(D50:D163))} -> 0 | G50: {=SUMPRODUCT($A$6^($K$1:$DT$1),K50:DT50)} -> 16.936917 | H50: =(1-$A$4/$A$9*F50)/$A$15 -> 33.872554 | I50: =G50-(12-1)/2/12-(12^2-1)/12/12^2*(E50+LN(1+$A$4)) -> 16.476137 | K50: 1 | L50: {=IFERROR(K50*(1-INDEX($D50:$D$71,L$1)),0)} -> 1 | M50: {=IFERROR(L50*(1-INDEX($D50:$D$71,M$1)),0)} -> 1 | N50: {=IFERROR(M50*(1-INDEX($D50:$D$71,N$1)),0)} -> 1 | O50: {=IFERROR(N50*(1-INDEX($D50:$D$71,O$1)),0)} -> 1 | P50: {=IFERROR(O50*(1-INDEX($D50:$D$71,P$1)),0)} -> 1 | Q50: {=IFERROR(P50*(1-INDEX($D50:$D$71,Q$1)),0)} -> 1 | R50: {=IFERROR(Q50*(1-INDEX($D50:$D$71,R$1)),0)} -> 1 | S50: {=IFERROR(R50*(1-INDEX($D50:$D$71,S$1)),0)} -> 1 | ... DX50: {=IFERROR(DW50*(1-INDEX($D50:$D$71,DX$1)),0)} -> 0
C51: 113 | D51: =EF51 -> 0 | E51: =-1/2*(LN(1-D50)+LN(1-D51)) -> 0 | F51: {=SUMPRODUCT($A$6^($K$1:$DT$1+1),K51:DT51,TRANSPOSE(D51:D164))} -> 0 | G51: {=SUMPRODUCT($A$6^($K$1:$DT$1),K51:DT51)} -> 16.415024 | H51: =(1-$A$4/$A$9*F51)/$A$15 -> 33.872554 | I51: =G51-(12-1)/2/12-(12^2-1)/12/12^2*(E51+LN(1+$A$4)) -> 15.954245 | K51: 1 | L51: {=IFERROR(K51*(1-INDEX($D51:$D$71,L$1)),0)} -> 1 | M51: {=IFERROR(L51*(1-INDEX($D51:$D$71,M$1)),0)} -> 1 | N51: {=IFERROR(M51*(1-INDEX($D51:$D$71,N$1)),0)} -> 1 | O51: {=IFERROR(N51*(1-INDEX($D51:$D$71,O$1)),0)} -> 1 | P51: {=IFERROR(O51*(1-INDEX($D51:$D$71,P$1)),0)} -> 1 | Q51: {=IFERROR(P51*(1-INDEX($D51:$D$71,Q$1)),0)} -> 1 | R51: {=IFERROR(Q51*(1-INDEX($D51:$D$71,R$1)),0)} -> 1 | S51: {=IFERROR(R51*(1-INDEX($D51:$D$71,S$1)),0)} -> 1 | ... DX51: {=IFERROR(DW51*(1-INDEX($D51:$D$71,DX$1)),0)} -> 0
C52: 114 | D52: =EF52 -> 0 | E52: =-1/2*(LN(1-D51)+LN(1-D52)) -> 0 | F52: {=SUMPRODUCT($A$6^($K$1:$DT$1+1),K52:DT52,TRANSPOSE(D52:D165))} -> 0 | G52: {=SUMPRODUCT($A$6^($K$1:$DT$1),K52:DT52)} -> 15.877475 | H52: =(1-$A$4/$A$9*F52)/$A$15 -> 33.872554 | I52: =G52-(12-1)/2/12-(12^2-1)/12/12^2*(E52+LN(1+$A$4)) -> 15.416695 | K52: 1 | L52: {=IFERROR(K52*(1-INDEX($D52:$D$71,L$1)),0)} -> 1 | M52: {=IFERROR(L52*(1-INDEX($D52:$D$71,M$1)),0)} -> 1 | N52: {=IFERROR(M52*(1-INDEX($D52:$D$71,N$1)),0)} -> 1 | O52: {=IFERROR(N52*(1-INDEX($D52:$D$71,O$1)),0)} -> 1 | P52: {=IFERROR(O52*(1-INDEX($D52:$D$71,P$1)),0)} -> 1 | Q52: {=IFERROR(P52*(1-INDEX($D52:$D$71,Q$1)),0)} -> 1 | R52: {=IFERROR(Q52*(1-INDEX($D52:$D$71,R$1)),0)} -> 1 | S52: {=IFERROR(R52*(1-INDEX($D52:$D$71,S$1)),0)} -> 1 | ... DX52: {=IFERROR(DW52*(1-INDEX($D52:$D$71,DX$1)),0)} -> 0
C53: 115 | D53: =EF53 -> 0 | E53: =-1/2*(LN(1-D52)+LN(1-D53)) -> 0 | F53: {=SUMPRODUCT($A$6^($K$1:$DT$1+1),K53:DT53,TRANSPOSE(D53:D166))} -> 0 | G53: {=SUMPRODUCT($A$6^($K$1:$DT$1),K53:DT53)} -> 15.323799 | H53: =(1-$A$4/$A$9*F53)/$A$15 -> 33.872554 | I53: =G53-(12-1)/2/12-(12^2-1)/12/12^2*(E53+LN(1+$A$4)) -> 14.86302 | K53: 1 | L53: {=IFERROR(K53*(1-INDEX($D53:$D$71,L$1)),0)} -> 1 | M53: {=IFERROR(L53*(1-INDEX($D53:$D$71,M$1)),0)} -> 1 | N53: {=IFERROR(M53*(1-INDEX($D53:$D$71,N$1)),0)} -> 1 | O53: {=IFERROR(N53*(1-INDEX($D53:$D$71,O$1)),0)} -> 1 | P53: {=IFERROR(O53*(1-INDEX($D53:$D$71,P$1)),0)} -> 1 | Q53: {=IFERROR(P53*(1-INDEX($D53:$D$71,Q$1)),0)} -> 1 | R53: {=IFERROR(Q53*(1-INDEX($D53:$D$71,R$1)),0)} -> 1 | S53: {=IFERROR(R53*(1-INDEX($D53:$D$71,S$1)),0)} -> 1 | ... DX53: {=IFERROR(DW53*(1-INDEX($D53:$D$71,DX$1)),0)} -> 0
C54: 116 | D54: =EF54 -> 0 | E54: =-1/2*(LN(1-D53)+LN(1-D54)) -> 0 | F54: {=SUMPRODUCT($A$6^($K$1:$DT$1+1),K54:DT54,TRANSPOSE(D54:D167))} -> 0 | G54: {=SUMPRODUCT($A$6^($K$1:$DT$1),K54:DT54)} -> 14.753513 | H54: =(1-$A$4/$A$9*F54)/$A$15 -> 33.872554 | I54: =G54-(12-1)/2/12-(12^2-1)/12/12^2*(E54+LN(1+$A$4)) -> 14.292734 | K54: 1 | L54: {=IFERROR(K54*(1-INDEX($D54:$D$71,L$1)),0)} -> 1 | M54: {=IFERROR(L54*(1-INDEX($D54:$D$71,M$1)),0)} -> 1 | N54: {=IFERROR(M54*(1-INDEX($D54:$D$71,N$1)),0)} -> 1 | O54: {=IFERROR(N54*(1-INDEX($D54:$D$71,O$1)),0)} -> 1 | P54: {=IFERROR(O54*(1-INDEX($D54:$D$71,P$1)),0)} -> 1 | Q54: {=IFERROR(P54*(1-INDEX($D54:$D$71,Q$1)),0)} -> 1 | R54: {=IFERROR(Q54*(1-INDEX($D54:$D$71,R$1)),0)} -> 1 | S54: {=IFERROR(R54*(1-INDEX($D54:$D$71,S$1)),0)} -> 1 | ... DX54: {=IFERROR(DW54*(1-INDEX($D54:$D$71,DX$1)),0)} -> 0
C55: 117 | D55: =EF55 -> 0 | E55: =-1/2*(LN(1-D54)+LN(1-D55)) -> 0 | F55: {=SUMPRODUCT($A$6^($K$1:$DT$1+1),K55:DT55,TRANSPOSE(D55:D168))} -> 0 | G55: {=SUMPRODUCT($A$6^($K$1:$DT$1),K55:DT55)} -> 14.166118 | H55: =(1-$A$4/$A$9*F55)/$A$15 -> 33.872554 | I55: =G55-(12-1)/2/12-(12^2-1)/12/12^2*(E55+LN(1+$A$4)) -> 13.705339 | K55: 1 | L55: {=IFERROR(K55*(1-INDEX($D55:$D$71,L$1)),0)} -> 1 | M55: {=IFERROR(L55*(1-INDEX($D55:$D$71,M$1)),0)} -> 1 | N55: {=IFERROR(M55*(1-INDEX($D55:$D$71,N$1)),0)} -> 1 | O55: {=IFERROR(N55*(1-INDEX($D55:$D$71,O$1)),0)} -> 1 | P55: {=IFERROR(O55*(1-INDEX($D55:$D$71,P$1)),0)} -> 1 | Q55: {=IFERROR(P55*(1-INDEX($D55:$D$71,Q$1)),0)} -> 1 | R55: {=IFERROR(Q55*(1-INDEX($D55:$D$71,R$1)),0)} -> 1 | S55: {=IFERROR(R55*(1-INDEX($D55:$D$71,S$1)),0)} -> 1 | ... DX55: {=IFERROR(DW55*(1-INDEX($D55:$D$71,DX$1)),0)} -> 0
C56: 118 | D56: =EF56 -> 0 | E56: =-1/2*(LN(1-D55)+LN(1-D56)) -> 0 | F56: {=SUMPRODUCT($A$6^($K$1:$DT$1+1),K56:DT56,TRANSPOSE(D56:D169))} -> 0 | G56: {=SUMPRODUCT($A$6^($K$1:$DT$1),K56:DT56)} -> 13.561102 | H56: =(1-$A$4/$A$9*F56)/$A$15 -> 33.872554 | I56: =G56-(12-1)/2/12-(12^2-1)/12/12^2*(E56+LN(1+$A$4)) -> 13.100323 | K56: 1 | L56: {=IFERROR(K56*(1-INDEX($D56:$D$71,L$1)),0)} -> 1 | M56: {=IFERROR(L56*(1-INDEX($D56:$D$71,M$1)),0)} -> 1 | N56: {=IFERROR(M56*(1-INDEX($D56:$D$71,N$1)),0)} -> 1 | O56: {=IFERROR(N56*(1-INDEX($D56:$D$71,O$1)),0)} -> 1 | P56: {=IFERROR(O56*(1-INDEX($D56:$D$71,P$1)),0)} -> 1 | Q56: {=IFERROR(P56*(1-INDEX($D56:$D$71,Q$1)),0)} -> 1 | R56: {=IFERROR(Q56*(1-INDEX($D56:$D$71,R$1)),0)} -> 1 | S56: {=IFERROR(R56*(1-INDEX($D56:$D$71,S$1)),0)} -> 1 | ... DX56: {=IFERROR(DW56*(1-INDEX($D56:$D$71,DX$1)),0)} -> 0
C57: 119 | D57: =EF57 -> 0 | E57: =-1/2*(LN(1-D56)+LN(1-D57)) -> 0 | F57: {=SUMPRODUCT($A$6^($K$1:$DT$1+1),K57:DT57,TRANSPOSE(D57:D170))} -> 0 | G57: {=SUMPRODUCT($A$6^($K$1:$DT$1),K57:DT57)} -> 12.937935 | H57: =(1-$A$4/$A$9*F57)/$A$15 -> 33.872554 | I57: =G57-(12-1)/2/12-(12^2-1)/12/12^2*(E57+LN(1+$A$4)) -> 12.477156 | K57: 1 | L57: {=IFERROR(K57*(1-INDEX($D57:$D$71,L$1)),0)} -> 1 | M57: {=IFERROR(L57*(1-INDEX($D57:$D$71,M$1)),0)} -> 1 | N57: {=IFERROR(M57*(1-INDEX($D57:$D$71,N$1)),0)} -> 1 | O57: {=IFERROR(N57*(1-INDEX($D57:$D$71,O$1)),0)} -> 1 | P57: {=IFERROR(O57*(1-INDEX($D57:$D$71,P$1)),0)} -> 1 | Q57: {=IFERROR(P57*(1-INDEX($D57:$D$71,Q$1)),0)} -> 1 | R57: {=IFERROR(Q57*(1-INDEX($D57:$D$71,R$1)),0)} -> 1 | S57: {=IFERROR(R57*(1-INDEX($D57:$D$71,S$1)),0)} -> 1 | ... DX57: {=IFERROR(DW57*(1-INDEX($D57:$D$71,DX$1)),0)} -> 0
C58: 120 | D58: =EF58 -> 0 | E58: =-1/2*(LN(1-D57)+LN(1-D58)) -> 0 | F58: {=SUMPRODUCT($A$6^($K$1:$DT$1+1),K58:DT58,TRANSPOSE(D58:D171))} -> 0 | G58: {=SUMPRODUCT($A$6^($K$1:$DT$1),K58:DT58)} -> 12.296073 | H58: =(1-$A$4/$A$9*F58)/$A$15 -> 33.872554 | I58: =G58-(12-1)/2/12-(12^2-1)/12/12^2*(E58+LN(1+$A$4)) -> 11.835294 | K58: 1 | L58: {=IFERROR(K58*(1-INDEX($D58:$D$71,L$1)),0)} -> 1 | M58: {=IFERROR(L58*(1-INDEX($D58:$D$71,M$1)),0)} -> 1 | N58: {=IFERROR(M58*(1-INDEX($D58:$D$71,N$1)),0)} -> 1 | O58: {=IFERROR(N58*(1-INDEX($D58:$D$71,O$1)),0)} -> 1 | P58: {=IFERROR(O58*(1-INDEX($D58:$D$71,P$1)),0)} -> 1 | Q58: {=IFERROR(P58*(1-INDEX($D58:$D$71,Q$1)),0)} -> 1 | R58: {=IFERROR(Q58*(1-INDEX($D58:$D$71,R$1)),0)} -> 1 | S58: {=IFERROR(R58*(1-INDEX($D58:$D$71,S$1)),0)} -> 1 | ... DX58: {=IFERROR(DW58*(1-INDEX($D58:$D$71,DX$1)),0)} -> 0
C59: 121 | D59: =EF59 -> 0 | E59: =-1/2*(LN(1-D58)+LN(1-D59)) -> 0 | F59: {=SUMPRODUCT($A$6^($K$1:$DT$1+1),K59:DT59,TRANSPOSE(D59:D172))} -> 0 | G59: {=SUMPRODUCT($A$6^($K$1:$DT$1),K59:DT59)} -> 11.634955 | H59: =(1-$A$4/$A$9*F59)/$A$15 -> 33.872554 | I59: =G59-(12-1)/2/12-(12^2-1)/12/12^2*(E59+LN(1+$A$4)) -> 11.174176 | K59: 1 | L59: {=IFERROR(K59*(1-INDEX($D59:$D$71,L$1)),0)} -> 1 | M59: {=IFERROR(L59*(1-INDEX($D59:$D$71,M$1)),0)} -> 1 | N59: {=IFERROR(M59*(1-INDEX($D59:$D$71,N$1)),0)} -> 1 | O59: {=IFERROR(N59*(1-INDEX($D59:$D$71,O$1)),0)} -> 1 | P59: {=IFERROR(O59*(1-INDEX($D59:$D$71,P$1)),0)} -> 1 | Q59: {=IFERROR(P59*(1-INDEX($D59:$D$71,Q$1)),0)} -> 1 | R59: {=IFERROR(Q59*(1-INDEX($D59:$D$71,R$1)),0)} -> 1 | S59: {=IFERROR(R59*(1-INDEX($D59:$D$71,S$1)),0)} -> 1 | ... DX59: {=IFERROR(DW59*(1-INDEX($D59:$D$71,DX$1)),0)} -> 0
C60: 122 | D60: =EF60 -> 0 | E60: =-1/2*(LN(1-D59)+LN(1-D60)) -> 0 | F60: {=SUMPRODUCT($A$6^($K$1:$DT$1+1),K60:DT60,TRANSPOSE(D60:D173))} -> 0 | G60: {=SUMPRODUCT($A$6^($K$1:$DT$1),K60:DT60)} -> 10.954004 | H60: =(1-$A$4/$A$9*F60)/$A$15 -> 33.872554 | I60: =G60-(12-1)/2/12-(12^2-1)/12/12^2*(E60+LN(1+$A$4)) -> 10.493225 | K60: 1 | L60: {=IFERROR(K60*(1-INDEX($D60:$D$71,L$1)),0)} -> 1 | M60: {=IFERROR(L60*(1-INDEX($D60:$D$71,M$1)),0)} -> 1 | N60: {=IFERROR(M60*(1-INDEX($D60:$D$71,N$1)),0)} -> 1 | O60: {=IFERROR(N60*(1-INDEX($D60:$D$71,O$1)),0)} -> 1 | P60: {=IFERROR(O60*(1-INDEX($D60:$D$71,P$1)),0)} -> 1 | Q60: {=IFERROR(P60*(1-INDEX($D60:$D$71,Q$1)),0)} -> 1 | R60: {=IFERROR(Q60*(1-INDEX($D60:$D$71,R$1)),0)} -> 1 | S60: {=IFERROR(R60*(1-INDEX($D60:$D$71,S$1)),0)} -> 1 | ... DX60: {=IFERROR(DW60*(1-INDEX($D60:$D$71,DX$1)),0)} -> 0
...

Sheet Payments
B1: Qualified Age | C1: Income | D1: Residency | F1: B(65,0) | G1: Max Income | H1: 75 and above | K1: Interest | L1: i_12 | M1: d | N1: d_12 | DO1: mu_75 | DP1: A_75 | DQ1: a_75 | DR1: (UDD) | DS1: (WH3)
B2: =65+MAX(10-$D$2,0) -> 65 | C2: =Calculations!B3 -> 142609 | D2: =Calculations!D3 -> 15 | F2: =727.67*MAX(FLOOR(MIN($D$2,40),1),10)/40 -> 272.87625 | G2: =Calculations!B9 -> 142609 | H2: =Calculations!C9 -> 148179 | K2: =Calculations!B6 -> 0.03 | L2: =12*((1+K2)^(1/12)-1) -> 0.029595237 | M2: =1-1/(1+K2) -> 0.029126214 | N2: =(1-(1+K2)^(-1/12))*12 -> 0.029522427 | DO2: ='Life Table'!E13 -> 0.028389182 | DP2: ='Life Table'!F13 -> 0.70222735 | DQ2: ='Life Table'!G13 -> 10.223528 | DR2: ='Life Table'!H13 -> 9.7610048 | DS2: ='Life Table'!I13 -> 9.7603988
B3: k | C3: 0 | D3: 1 | E3: 2 | F3: 3 | G3: 4 | H3: 5 | I3: 6 | J3: 7 | K3: 8 | L3: 9 | M3: 10 | N3: 11 | O3: 12 | P3: 13 | Q3: 14 | R3: 15 | S3: 16 | T3: 17 | U3: 18 | V3: 19 | W3: 20 | X3: 21 | Y3: 22 | Z3: 23 | AA3: 24 | AB3: 25 | AC3: 26 | AD3: 27 | AE3: 28 | AF3: 29 | AG3: 30 | AH3: 31 | AI3: 32 | AJ3: 33 | AK3: 34 | AL3: 35 | AM3: 36 | AN3: 37 | AO3: 38 | AP3: 39 | AQ3: 40 | AR3: 41 | AS3: 42 | AT3: 43 | AU3: 44 | AV3: 45 | AW3: 46 | AX3: 47 | AY3: 48 | AZ3: 49 | BA3: 50 | BB3: 51 | BC3: 52 | BD3: 53 | BE3: 54 | BF3: 55 | BG3: 56 | BH3: 57 | BI3: 58 | BJ3: 59 | BK3: 60 | BL3: 61 | BM3: 62 | BN3: 63 | BO3: 64 | BP3: 65 | BQ3: 66 | BR3: 67 | BS3: 68 | BT3: 69 | BU3: 70 | BV3: 71 | BW3: 72 | BX3: 73 | BY3: 74 | BZ3: 75 | CA3: 76 | CB3: 77 | CC3: 78 | CD3: 79 | CE3: 80 | CF3: 81 | CG3: 82 | CH3: 83 | CI3: 84 | CJ3: 85 | CK3: 86 | CL3: 87 | CM3: 88 | CN3: 89 | CO3: 90 | CP3: 91 | CQ3: 92 | CR3: 93 | CS3: 94 | CT3: 95 | CU3: 96 | CV3: 97 | CW3: 98 | CX3: 99 | CY3: 100 | CZ3: 101 | DA3: 102 | DB3: 103 | DC3: 104 | DD3: 105 | DE3: 106 | DF3: 107 | DG3: 108 | DH3: 109 | DI3: 110 | DJ3: 111 | DK3: 112 | DL3: 113 | DM3: 114 | DN3: 115 | DO3: 116 | DP3: 117 | DQ3: 118 | DR3: 119 | DS3: 120
B4: k/12_p_65 | C4: {=INDEX('Life Table'!$L$3:$BF$71,1,1+FLOOR(C3/12,1))*(1-(C3/12-FLOOR(C3/12,1))*INDEX('Life Table'!$D$3:$D$71,1+FLOOR(C3/12,1)))} -> 1 | D4: {=INDEX('Life Table'!$L$3:$BF$71,1,1+FLOOR(D3/12,1))*(1-(D3/12-FLOOR(D3/12,1))*INDEX('Life Table'!$D$3:$D$71,1+FLOOR(D3/12,1)))} -> 0.9990535 | E4: {=INDEX('Life Table'!$L$3:$BF$71,1,1+FLOOR(E3/12,1))*(1-(E3/12-FLOOR(E3/12,1))*INDEX('Life Table'!$D$3:$D$71,1+FLOOR(E3/12,1)))} -> 0.998107 | F4: {=INDEX('Life Table'!$L$3:$BF$71,1,1+FLOOR(F3/12,1))*(1-(F3/12-FLOOR(F3/12,1))*INDEX('Life Table'!$D$3:$D$71,1+FLOOR(F3/12,1)))} -> 0.9971605 | G4: {=INDEX('Life Table'!$L$3:$BF$71,1,1+FLOOR(G3/12,1))*(1-(G3/12-FLOOR(G3/12,1))*INDEX('Life Table'!$D$3:$D$71,1+FLOOR(G3/12,1)))} -> 0.996214 | H4: {=INDEX('Life Table'!$L$3:$BF$71,1,1+FLOOR(H3/12,1))*(1-(H3/12-FLOOR(H3/12,1))*INDEX('Life Table'!$D$3:$D$71,1+FLOOR(H3/12,1)))} -> 0.9952675 | I4: {=INDEX('Life Table'!$L$3:$BF$71,1,1+FLOOR(I3/12,1))*(1-(I3/12-FLOOR(I3/12,1))*INDEX('Life Table'!$D$3:$D$71,1+FLOOR(I3/12,1)))} -> 0.994321 | J4: {=INDEX('Life Table'!$L$3:$BF$71,1,1+FLOOR(J3/12,1))*(1-(J3/12-FLOOR(J3/12,1))*INDEX('Life Table'!$D$3:$D$71,1+FLOOR(J3/12,1)))} -> 0.9933745 | ... DS4: {=INDEX('Life Table'!$L$3:$BF$71,1,1+FLOOR(DS3/12,1))*(1-(DS3/12-FLOOR(DS3/12,1))*INDEX('Life Table'!$D$3:$D$71,1+FLOOR(DS3/12,1)))} -> 0.83444024
B5: k/12_E_65 | C5: =C4/(1+$L$2/12)^C3 -> 1 | D5: =D4/(1+$L$2/12)^D3 -> 0.99659563 | E5: =E4/(1+$L$2/12)^E3 -> 0.99320195 | F5: =F4/(1+$L$2/12)^F3 -> 0.98981894 | G5: =G4/(1+$L$2/12)^G3 -> 0.98644657 | H5: =H4/(1+$L$2/12)^H3 -> 0.98308479 | I5: =I4/(1+$L$2/12)^I3 -> 0.97973359 | J5: =J4/(1+$L$2/12)^J3 -> 0.97639293 | ... DS5: =DS4/(1+$L$2/12)^DS3 -> 0.6209019
B6: Received Age | C6: 65 | D6: =$C$6+D3/12 -> 65.083333 | E6: =$C$6+E3/12 -> 65.166667 | F6: =$C$6+F3/12 -> 65.25 | G6: =$C$6+G3/12 -> 65.333333 | H6: =$C$6+H3/12 -> 65.416667 | I6: =$C$6+I3/12 -> 65.5 | J6: =$C$6+J3/12 -> 65.583333 | K6: =$C$6+K3/12 -> 65.666667 | ... DS6: =$C$6+DS3/12 -> 75
A7: u | B7: Deferred Age | DT7: PV
A8: 0 | B8: =65 -> 65 | C8: =$F$2*IF(C$6<$B8,0,1)*(1+0.072*MAX(MIN($B8,70)-$B$2,0))*IF(C$6>=75,1.1,1)*IF($B8<75,IF($C$2<=$G$2,1,0),IF($C$2<=$H$2,1,0))*IF(OR(C$6<$B$2,$B8<$B$2),0,1) -> 272.87625 | D8: =$F$2*IF(D$6<$B8,0,1)*(1+0.072*MAX(MIN($B8,70)-$B$2,0))*IF(D$6>=75,1.1,1)*IF($B8<75,IF($C$2<=$G$2,1,0),IF($C$2<=$H$2,1,0))*IF(OR(D$6<$B$2,$B8<$B$2),0,1) -> 272.87625 | E8: =$F$2*IF(E$6<$B8,0,1)*(1+0.072*MAX(MIN($B8,70)-$B$2,0))*IF(E$6>=75,1.1,1)*IF($B8<75,IF($C$2<=$G$2,1,0),IF($C$2<=$H$2,1,0))*IF(OR(E$6<$B$2,$B8<$B$2),0,1) -> 272.87625 | F8: =$F$2*IF(F$6<$B8,0,1)*(1+0.072*MAX(MIN($B8,70)-$B$2,0))*IF(F$6>=75,1.1,1)*IF($B8<75,IF($C$2<=$G$2,1,0),IF($C$2<=$H$2,1,0))*IF(OR(F$6<$B$2,$B8<$B$2),0,1) -> 272.87625 | G8: =$F$2*IF(G$6<$B8,0,1)*(1+0.072*MAX(MIN($B8,70)-$B$2,0))*IF(G$6>=75,1.1,1)*IF($B8<75,IF($C$2<=$G$2,1,0),IF($C$2<=$H$2,1,0))*IF(OR(G$6<$B$2,$B8<$B$2),0,1) -> 272.87625 | H8: =$F$2*IF(H$6<$B8,0,1)*(1+0.072*MAX(MIN($B8,70)-$B$2,0))*IF(H$6>=75,1.1,1)*IF($B8<75,IF($C$2<=$G$2,1,0),IF($C$2<=$H$2,1,0))*IF(OR(H$6<$B$2,$B8<$B$2),0,1) -> 272.87625 | I8: =$F$2*IF(I$6<$B8,0,1)*(1+0.072*MAX(MIN($B8,70)-$B$2,0))*IF(I$6>=75,1.1,1)*IF($B8<75,IF($C$2<=$G$2,1,0),IF($C$2<=$H$2,1,0))*IF(OR(I$6<$B$2,$B8<$B$2),0,1) -> 272.87625 | J8: =$F$2*IF(J$6<$B8,0,1)*(1+0.072*MAX(MIN($B8,70)-$B$2,0))*IF(J$6>=75,1.1,1)*IF($B8<75,IF($C$2<=$G$2,1,0),IF($C$2<=$H$2,1,0))*IF(OR(J$6<$B$2,$B8<$B$2),0,1) -> 272.87625 | ... DS8: =$F$2*IF(DS$6<$B8,0,1)*(1+0.072*MAX(MIN($B8,70)-$B$2,0))*IF(DS$6>=75,1.1,1)*IF($B8<75,IF($C$2<=$G$2,1,0),IF($C$2<=$H$2,1,0))*IF(OR(DS$6<$B$2,$B8<$B$2),0,1) -> 300.16388 | DT8: =SUMPRODUCT($C$5:$DR$5,C8:DR8)+DS8*12*$DR$2 -> 61623.917
